Workbook

Sheet Planilha1
Z1: 47850 | AJ1: 46389
Z2: 100000
B3: Data | C3: Fechamento WSP(S&P) | D3: Data | E3: Fechamento DOL PTAX | F3: Data | G3: Fechamento T10 | H3: T10 adj | I3: Data | J3: Fechamento WDO | L3: Data | M3: Fechamento DAPQ26 | N3: Data | O3: Fechamento DAPK27 | P3: Data | Q3: Fechamento DAPQ28 | R3: Data | S3: Fechamento DAPQ30 | T3: Data | U3: Fechamento DAPQ32 | V3: Data | W3: Fechamento DAPK35 | X3: Data | Y3: du | Z3: Fechamento | AD3: vol1 | AE3: retorno1 | AF3: peso1 | AG3: var1 | AJ3: Data | AK3: du | AL3: Fechamento | AP3: ret1*w1 | AQ3: ret2*w2 | AR3: ret port | AT3: VaR 95% portfolio | AU3: 60000 | AV3: 0.0001
B4: 45639 | C4: 6033.98 | D4: 45639 | E4: 6.0394 | F4: 45639 | G4: 109.925 | H4: =G4*E4*1000 -> 663881.04 | I4: 45639 | J4: 6073.5 | K4: =J4*10 -> 60735 | L4: 45639 | M4: 8.22 | N4: 45639 | O4: 8.03 | P4: 45639 | Q4: 7.79 | R4: 45639 | S4: 7.3 | T4: 45639 | U4: 7.14 | V4: 45639 | W4: 6.9 | X4: 45639 | Y4: =NETWORKDAYS(X4,$Z$1,FERIADO!$A$2:$A$408) -> 1528 | Z4: 14.04 | AA4: =$Z$2/(1+Z4/100)^(Y4/252) -> 45085.207 | AB4: =LOG(AA4/AA5) -> -0.0041674776 | AD4: =_xlfn.STDEV.S(AB4:AB1237)*SQRT(252) -> 0.08837353 | AE4: {=AVERAGE(AB4:AB1237*252)} -> -0.003236543 | AF4: 0.5 | AG4: =_xlfn.PERCENTILE.INC(AB4:AB1237,0.05) -> -0.0075368286 | AJ4: 45639 | AK4: =NETWORKDAYS(AJ4,$AJ$1,FERIADO!$A$2:$A$408) -> 515 | AL4: 14.885 | AM4: =$Z$2/(1+AL4/100)^(AK4/252) -> 75308.292 | AN4: =LOG(AM4/AM5) -> -0.0011164836 | AP4: =AB4*$AF$4 -> -0.0020837388 | AQ4: =AN4*$AF$7 -> -0.00033494507 | AR4: =AQ4+AP4 -> -0.0024186839 | AT4: VaR 95% | AU4: =_xlfn.PERCENTILE.INC(AR4:AR1237,0.05) -> -0.0050019286
B5: 45638 | C5: 6045.59 | D5: 45638 | E5: 5.9402 | F5: 45638 | G5: 110.351 | H5: =G5*E5*1000 -> 655507.01 | I5: 45638 | J5: 5984.5 | K5: =J5*10 -> 59845 | L5: 45638 | M5: 8.07 | N5: 45638 | O5: 7.85 | P5: 45638 | Q5: 7.66 | R5: 45638 | S5: 7.24 | T5: 45638 | U5: 7.07 | V5: 45638 | W5: 6.94 | X5: 45638 | Y5: =NETWORKDAYS(X5,$Z$1,FERIADO!$A$2:$A$408) -> 1529 | Z5: 13.85 | AA5: =$Z$2/(1+Z5/100)^(Y5/252) -> 45519.926 | AB5: =LOG(AA5/AA6) -> -0.0062692976 | AJ5: 45638 | AK5: =NETWORKDAYS(AJ5,$AJ$1,FERIADO!$A$2:$A$408) -> 516 | AL5: 14.71 | AM5: =$Z$2/(1+AL5/100)^(AK5/252) -> 75502.144 | AN5: =LOG(AM5/AM6) -> -0.002564131 | AP5: =AB5*$AF$4 -> -0.0031346488 | AQ5: =AN5*$AF$7 -> -0.0007692393 | AR5: =AQ5+AP5 -> -0.0039038881
B6: 45637 | C6: 6085.3 | D6: 45637 | E6: 6.0314 | F6: 45637 | G6: 110.669 | H6: =G6*E6*1000 -> 667489.01 | I6: 45637 | J6: 5965 | K6: =J6*10 -> 59650 | L6: 45637 | M6: 7.56 | N6: 45637 | O6: 7.46 | P6: 45637 | Q6: 7.34 | R6: 45637 | S6: 7.05 | T6: 45637 | U6: 6.97 | V6: 45637 | W6: 6.81 | X6: 45637 | Y6: =NETWORKDAYS(X6,$Z$1,FERIADO!$A$2:$A$408) -> 1530 | Z6: 13.57 | AA6: =$Z$2/(1+Z6/100)^(Y6/252) -> 46181.799 | AB6: =LOG(AA6/AA7) -> 0.0081065387 | AD6: vol2 | AE6: retorno2 | AF6: peso2 | AG6: var2 | AJ6: 45637 | AK6: =NETWORKDAYS(AJ6,$AJ$1,FERIADO!$A$2:$A$408) -> 517 | AL6: 14.35 | AM6: =$Z$2/(1+AL6/100)^(AK6/252) -> 75949.237 | AN6: =LOG(AM6/AM7) -> 0.0024922244 | AP6: =AB6*$AF$4 -> 0.0040532693 | AQ6: =AN6*$AF$7 -> 0.00074766731 | AR6: =AQ6+AP6 -> 0.0048009367 | AT6: 1 | AU6: =AM4 -> 75308.292 | AV6: =AU6/$AU$8*$AV$8 -> -376.6867 | AW6: =$AU$3/AV6 -> -159.28356
B7: 45636 | C7: 6031.88 | D7: 45636 | E7: 6.0523 | F7: 45636 | G7: 110.927 | H7: =G7*E7*1000 -> 671363.48 | I7: 45636 | J7: 6057.5 | K7: =J7*10 -> 60575 | L7: 45636 | M7: 7.63 | N7: 45636 | O7: 7.6 | P7: 45636 | Q7: 7.53 | R7: 45636 | S7: 7.25 | T7: 45636 | U7: 7.14 | V7: 45636 | W7: 6.97 | X7: 45636 | Y7: =NETWORKDAYS(X7,$Z$1,FERIADO!$A$2:$A$408) -> 1531 | Z7: 13.91 | AA7: =$Z$2/(1+Z7/100)^(Y7/252) -> 45327.765 | AB7: =LOG(AA7/AA8) -> 0.010403237 | AD7: =_xlfn.STDEV.S(AN4:AN1237)*SQRT(252) -> 0.054886846 | AE7: {=AVERAGE(AN4:AN1237*252)} -> 0.015493358 | AF7: 0.3 | AG7: =_xlfn.PERCENTILE.INC(AN4:AN1237,0.05) -> -0.0043249773 | AJ7: 45636 | AK7: =NETWORKDAYS(AJ7,$AJ$1,FERIADO!$A$2:$A$408) -> 518 | AL7: 14.64 | AM7: =$Z$2/(1+AL7/100)^(AK7/252) -> 75514.646 | AN7: =LOG(AM7/AM8) -> 0.0031953795 | AP7: =AB7*$AF$4 -> 0.0052016183 | AQ7: =AN7*$AF$7 -> 0.00095861386 | AR7: =AQ7+AP7 -> 0.0061602322 | AT7: 2 | AU7: =AA4 -> 45085.207 | AV7: =AU7/$AU$8*$AV$8 -> -225.51299 | AW7: =$AU$3/AV7 -> -266.06007
B8: 45635 | C8: 6047.66 | D8: 45635 | E8: 6.0564 | F8: 45635 | G8: 111.18 | H8: =G8*E8*1000 -> 673350.55 | I8: 45635 | J8: 6092 | K8: =J8*10 -> 60920 | L8: 45635 | M8: 7.76 | N8: 45635 | O8: 7.71 | P8: 45635 | Q8: 7.65 | R8: 45635 | S8: 7.34 | T8: 45635 | U8: 7.24 | V8: 45635 | W8: 7.08 | X8: 45635 | Y8: =NETWORKDAYS(X8,$Z$1,FERIADO!$A$2:$A$408) -> 1532 | Z8: 14.35 | AA8: =$Z$2/(1+Z8/100)^(Y8/252) -> 44254.87 | AB8: =LOG(AA8/AA9) -> -0.0060143974 | AJ8: 45635 | AK8: =NETWORKDAYS(AJ8,$AJ$1,FERIADO!$A$2:$A$408) -> 519 | AL8: 15.02 | AM8: =$Z$2/(1+AL8/100)^(AK8/252) -> 74961.076 | AN8: =LOG(AM8/AM9) -> -0.002333683 | AP8: =AB8*$AF$4 -> -0.0030071987 | AQ8: =AN8*$AF$7 -> -0.00070010489 | AR8: =AQ8+AP8 -> -0.0037073036 | AU8: =SUM(AU6:AU7) -> 120393.5 | AV8: =AU4*AU8 -> -602.19969
B9: 45632 | C9: 6082.65 | D9: 45632 | E9: 6.0287 | F9: 45632 | G9: 111.5 | H9: =G9*E9*1000 -> 672200.05 | I9: 45632 | J9: 6101.5 | K9: =J9*10 -> 61015 | L9: 45632 | M9: 7.68 | N9: 45632 | O9: 7.68 | P9: 45632 | Q9: 7.64 | R9: 45632 | S9: 7.3 | T9: 45632 | U9: 7.21 | V9: 45632 | W9: 7.05 | X9: 45632 | Y9: =NETWORKDAYS(X9,$Z$1,FERIADO!$A$2:$A$408) -> 1533 | Z9: 14.08 | AA9: =$Z$2/(1+Z9/100)^(Y9/252) -> 44872.004 | AB9: =LOG(AA9/AA10) -> -0.0027873063 | AD9: retorno diario | AE9: retorno na | AF9: cov | AG9: corr | AJ9: 45632 | AK9: =NETWORKDAYS(AJ9,$AJ$1,FERIADO!$A$2:$A$408) -> 520 | AL9: 14.69 | AM9: =$Z$2/(1+AL9/100)^(AK9/252) -> 75364.964 | AN9: =LOG(AM9/AM10) -> -0.0018015897 | AP9: =AB9*$AF$4 -> -0.0013936532 | AQ9: =AN9*$AF$7 -> -0.0005404769 | AR9: =AQ9+AP9 -> -0.0019341301
B10: 45631 | C10: 6080.81 | D10: 45631 | E10: 5.9843 | F10: 45631 | G10: 111.232 | H10: =G10*E10*1000 -> 665645.66 | I10: 45631 | J10: 6030 | K10: =J10*10 -> 60300 | L10: 45631 | M10: 7.49 | N10: 45631 | O10: 7.47 | P10: 45631 | Q10: 7.38 | R10: 45631 | S10: 7.16 | T10: 45631 | U10: 7.1 | V10: 45631 | W10: 6.95 | X10: 45631 | Y10: =NETWORKDAYS(X10,$Z$1,FERIADO!$A$2:$A$408) -> 1534 | Z10: 13.95 | AA10: =$Z$2/(1+Z10/100)^(Y10/252) -> 45160.919 | AB10: =LOG(AA10/AA11) -> -0.0011682393 | AD10: =AF4*AE4+AF7*AE7 -> 0.003029736 | AE10: =AF4*AD4+AF7*AD7 -> 0.060652819 | AF10: =_xlfn.COVARIANCE.S(AB4:AB1237,AN4:AN1237) -> 1.8444436e-05 | AG10: =CORREL(AB4:AB1237,AN4:AN1237) -> 0.95824254 | AJ10: 45631 | AK10: =NETWORKDAYS(AJ10,$AJ$1,FERIADO!$A$2:$A$408) -> 521 | AL10: 14.43 | AM10: =$Z$2/(1+AL10/100)^(AK10/252) -> 75678.251 | AN10: =LOG(AM10/AM11) -> -0.00067224457 | AP10: =AB10*$AF$4 -> -0.00058411964 | AQ10: =AN10*$AF$7 -> -0.00020167337 | AR10: =AQ10+AP10 -> -0.00078579301 | AT10: MVAR1 | AU10: 0.5 | AV10: =AU10*$AU$3 -> 30000
B11: 45630 | C11: 6088.16 | D11: 45630 | E11: 6.0575 | F11: 45630 | G11: 111.242 | H11: =G11*E11*1000 -> 673848.42 | I11: 45630 | J11: 6056 | K11: =J11*10 -> 60560 | L11: 45630 | M11: 7.43 | N11: 45630 | O11: 7.37 | P11: 45630 | Q11: 7.29 | R11: 45630 | S11: 7.13 | T11: 45630 | U11: 7.04 | V11: 45630 | W11: 6.94 | X11: 45630 | Y11: =NETWORKDAYS(X11,$Z$1,FERIADO!$A$2:$A$408) -> 1535 | Z11: 13.89 | AA11: =$Z$2/(1+Z11/100)^(Y11/252) -> 45282.564 | AB11: =LOG(AA11/AA12) -> 0.00092134288 | AD11: risco (vol) | AE11: risco (vol) an | AJ11: 45630 | AK11: =NETWORKDAYS(AJ11,$AJ$1,FERIADO!$A$2:$A$408) -> 522 | AL11: 14.315 | AM11: =$Z$2/(1+AL11/100)^(AK11/252) -> 75795.484 | AN11: =LOG(AM11/AM12) -> -0.00020319159 | AP11: =AB11*$AF$4 -> 0.00046067144 | AQ11: =AN11*$AF$7 -> -6.0957476e-05 | AR11: =AQ11+AP11 -> 0.00039971396 | AT11: MVAR2 | AU11: 0.3 | AV11: =AU11*$AU$3 -> 18000
B12: 45629 | C12: 6053.51 | D12: 45629 | E12: 6.0701 | F12: 45629 | G12: 110.9 | H12: =G12*E12*1000 -> 673174.09 | I12: 45629 | J12: 6059 | K12: =J12*10 -> 60590 | L12: 45629 | M12: 7.36 | N12: 45629 | O12: 7.35 | P12: 45629 | Q12: 7.3 | R12: 45629 | S12: 7.16 | T12: 45629 | U12: 7.11 | V12: 45629 | W12: 6.96 | X12: 45629 | Y12: =NETWORKDAYS(X12,$Z$1,FERIADO!$A$2:$A$408) -> 1536 | Z12: 13.92 | AA12: =$Z$2/(1+Z12/100)^(Y12/252) -> 45186.6 | AB12: =LOG(AA12/AA13) -> -0.0053617294 | AD12: =AF4^2*AD4^2+AF7^2*AD7^2+2*AF10*AF7*AF4 -> 0.0022291344 | AE12: =SQRT(AD12) -> 0.04721371 | AJ12: 45629 | AK12: =NETWORKDAYS(AJ12,$AJ$1,FERIADO!$A$2:$A$408) -> 523 | AL12: 14.26 | AM12: =$Z$2/(1+AL12/100)^(AK12/252) -> 75830.954 | AN12: =LOG(AM12/AM13) -> -0.0011544382 | AP12: =AB12*$AF$4 -> -0.0026808647 | AQ12: =AN12*$AF$7 -> -0.00034633146 | AR12: =AQ12+AP12 -> -0.0030271962
B13: 45628 | C13: 6047.62 | D13: 45628 | E13: 6.0628 | F13: 45628 | G13: 111.188 | H13: =G13*E13*1000 -> 674110.61 | I13: 45628 | J13: 6080.5 | K13: =J13*10 -> 60805 | L13: 45628 | M13: 7.18 | N13: 45628 | O13: 7.19 | P13: 45628 | Q13: 7.2 | R13: 45628 | S13: 7.08 | T13: 45628 | U13: 7.02 | V13: 45628 | W13: 6.88 | X13: 45628 | Y13: =NETWORKDAYS(X13,$Z$1,FERIADO!$A$2:$A$408) -> 1537 | Z13: 13.68 | AA13: =$Z$2/(1+Z13/100)^(Y13/252) -> 45747.925 | AB13: =LOG(AA13/AA14) -> -0.0016449767 | AJ13: 45628 | AK13: =NETWORKDAYS(AJ13,$AJ$1,FERIADO!$A$2:$A$408) -> 524 | AL13: 14.085 | AM13: =$Z$2/(1+AL13/100)^(AK13/252) -> 76032.795 | AN13: =LOG(AM13/AM14) -> -0.00012985697 | AP13: =AB13*$AF$4 -> -0.00082248835 | AQ13: =AN13*$AF$7 -> -3.895709e-05 | AR13: =AQ13+AP13 -> -0.00086144544
B14: 45625 | C14: 6026.86 | D14: 45625 | E14: 6.0529 | F14: 45625 | G14: 111.2 | H14: =G14*E14*1000 -> 673082.48 | I14: 45625 | J14: 6008 | K14: =J14*10 -> 60080 | L14: 45625 | M14: 7.27 | N14: 45625 | O14: 7.24 | P14: 45625 | Q14: 7.24 | R14: 45625 | S14: 7.12 | T14: 45625 | U14: 7.06 | V14: 45625 | W14: 6.94 | X14: 45625 | Y14: =NETWORKDAYS(X14,$Z$1,FERIADO!$A$2:$A$408) -> 1538 | Z14: 13.6 | AA14: =$Z$2/(1+Z14/100)^(Y14/252) -> 45921.533 | AB14: =LOG(AA14/AA15) -> 0.0037195998 | AE14: VaR port | AJ14: 45625 | AK14: =NETWORKDAYS(AJ14,$AJ$1,FERIADO!$A$2:$A$408) -> 525 | AL14: 14.04 | AM14: =$Z$2/(1+AL14/100)^(AK14/252) -> 76055.533 | AN14: =LOG(AM14/AM15) -> 0.00022641749 | AP14: =AB14*$AF$4 -> 0.0018597999 | AQ14: =AN14*$AF$7 -> 6.7925248e-05 | AR14: =AQ14+AP14 -> 0.0019277251
B15: 45624 | C15: 6003.59 | D15: 45624 | E15: 5.9865 | F15: 45624 | G15: 110.918 | H15: =G15*E15*1000 -> 664010.61 | I15: 45624 | J15: 6048 | K15: =J15*10 -> 60480 | L15: 45624 | M15: 7.14 | N15: 45624 | O15: 7.2 | P15: 45624 | Q15: 7.2 | R15: 45624 | S15: 7.13 | T15: 45624 | U15: 7.07 | V15: 45624 | W15: 6.98 | X15: 45624 | Y15: =NETWORKDAYS(X15,$Z$1,FERIADO!$A$2:$A$408) -> 1539 | Z15: 13.75 | AA15: =$Z$2/(1+Z15/100)^(Y15/252) -> 45529.908 | AB15: =LOG(AA15/AA16) -> -0.010532478 | AD15: =AF4^2*AG4^2+AF7^2*AG7^2+2*AF7*AF4*AG10*AG4*AG7 -> 2.5255073e-05 | AE15: =SQRT(AD15) -> 0.0050254426 | AJ15: 45624 | AK15: =NETWORKDAYS(AJ15,$AJ$1,FERIADO!$A$2:$A$408) -> 526 | AL15: 14.04 | AM15: =$Z$2/(1+AL15/100)^(AK15/252) -> 76015.892 | AN15: =LOG(AM15/AM16) -> -0.0031246829 | AP15: =AB15*$AF$4 -> -0.0052662392 | AQ15: =AN15*$AF$7 -> -0.00093740486 | AR15: =AQ15+AP15 -> -0.006203644
B16: 45623 | C16: 6001.25 | D16: 45623 | E16: 5.8285 | F16: 45623 | G16: 110.8 | H16: =G16*E16*1000 -> 645797.8 | I16: 45623 | J16: 5987.26 | K16: =J16*10 -> 59872.6 | L16: 45623 | M16: 7.17 | N16: 45623 | O16: 7.14 | P16: 45623 | Q16: 7.14 | R16: 45623 | S16: 7.05 | T16: 45623 | U16: 7.01 | V16: 45623 | W16: 6.92 | X16: 45623 | Y16: =NETWORKDAYS(X16,$Z$1,FERIADO!$A$2:$A$408) -> 1540 | Z16: 13.29 | AA16: =$Z$2/(1+Z16/100)^(Y16/252) -> 46647.594 | AB16: =LOG(AA16/AA17) -> -0.0087078907 | AF16: dVaRPort/dw1 | AJ16: 45623 | AK16: =NETWORKDAYS(AJ16,$AJ$1,FERIADO!$A$2:$A$408) -> 527 | AL16: 13.62 | AM16: =$Z$2/(1+AL16/100)^(AK16/252) -> 76564.787 | AN16: =LOG(AM16/AM17) -> -0.002145585 | AP16: =AB16*$AF$4 -> -0.0043539454 | AQ16: =AN16*$AF$7 -> -0.0006436755 | AR16: =AQ16+AP16 -> -0.0049976209
B17: 45622 | C17: 6025.23 | D17: 45622 | E17: 5.7984 | F17: 45622 | G17: 110.35 | H17: =G17*E17*1000 -> 639853.44 | I17: 45622 | J17: 5834.15 | K17: =J17*10 -> 58341.5 | L17: 45622 | M17: 7.02 | N17: 45622 | O17: 7 | P17: 45622 | Q17: 7 | R17: 45622 | S17: 6.92 | T17: 45622 | U17: 6.85 | V17: 45622 | W17: 6.74 | X17: 45622 | Y17: =NETWORKDAYS(X17,$Z$1,FERIADO!$A$2:$A$408) -> 1541 | Z17: 12.91 | AA17: =$Z$2/(1+Z17/100)^(Y17/252) -> 47592.349 | AB17: =LOG(AA17/AA18) -> 0.0016210505 | AE17: =AF4*AG4^2+AF7*AG10*AG7*AG4 -> 3.7772531e-05 | AF17: =AE17/$AE$15 -> 0.0075162595 | AJ17: 45622 | AK17: =NETWORKDAYS(AJ17,$AJ$1,FERIADO!$A$2:$A$408) -> 528 | AL17: 13.325 | AM17: =$Z$2/(1+AL17/100)^(AK17/252) -> 76943.983 | AN17: =LOG(AM17/AM18) -> 0.00041667539 | AP17: =AB17*$AF$4 -> 0.00081052526 | AQ17: =AN17*$AF$7 -> 0.00012500262 | AR17: =AQ17+AP17 -> 0.00093552788
B18: 45621 | C18: 5992.97 | D18: 45621 | E18: 5.7996 | F18: 45621 | G18: 110.505 | H18: =G18*E18*1000 -> 640884.8 | I18: 45621 | J18: 5824.61 | K18: =J18*10 -> 58246.1 | L18: 45621 | M18: 6.99 | N18: 45621 | O18: 6.98 | P18: 45621 | Q18: 6.97 | R18: 45621 | S18: 6.86 | T18: 45621 | U18: 6.82 | V18: 45621 | W18: 6.74 | X18: 45621 | Y18: =NETWORKDAYS(X18,$Z$1,FERIADO!$A$2:$A$408) -> 1542 | Z18: 12.97 | AA18: =$Z$2/(1+Z18/100)^(Y18/252) -> 47415.037 | AB18: =LOG(AA18/AA19) -> 0.0011515614 | AH18: VaRC | AJ18: 45621 | AK18: =NETWORKDAYS(AJ18,$AJ$1,FERIADO!$A$2:$A$408) -> 529 | AL18: 13.35 | AM18: =$Z$2/(1+AL18/100)^(AK18/252) -> 76870.196 | AN18: =LOG(AM18/AM19) -> 0.00041739125 | AP18: =AB18*$AF$4 -> 0.00057578068 | AQ18: =AN18*$AF$7 -> 0.00012521738 | AR18: =AQ18+AP18 -> 0.00070099806
B19: 45618 | C19: 5980.75 | D19: 45618 | E19: 5.8118 | F19: 45618 | G19: 109.61 | H19: =G19*E19*1000 -> 637031.4 | I19: 45618 | J19: 5833.15 | K19: =J19*10 -> 58331.5 | L19: 45618 | M19: 6.99 | N19: 45618 | O19: 7 | P19: 45618 | Q19: 6.99 | R19: 45618 | S19: 6.89 | T19: 45618 | U19: 6.85 | V19: 45618 | W19: 6.71 | X19: 45618 | Y19: =NETWORKDAYS(X19,$Z$1,FERIADO!$A$2:$A$408) -> 1543 | Z19: 13.01 | AA19: =$Z$2/(1+Z19/100)^(Y19/252) -> 47289.479 | AB19: =LOG(AA19/AA20) -> -0.00049568773 | AE19: MVAR1 | AF19: =AF17*AF4 -> 0.0037581298 | AG19: =AF19/AE15 -> 0.74782066 | AH19: =AF19*AA4 -> 169.43606 | AJ19: 45618 | AK19: =NETWORKDAYS(AJ19,$AJ$1,FERIADO!$A$2:$A$408) -> 530 | AL19: 13.375 | AM19: =$Z$2/(1+AL19/100)^(AK19/252) -> 76796.354 | AN19: =LOG(AM19/AM20) -> -2.5842309e-05 | AP19: =AB19*$AF$4 -> -0.00024784387 | AQ19: =AN19*$AF$7 -> -7.7526927e-06 | AR19: =AQ19+AP19 -> -0.00025559656
B20: 45617 | C20: 5965.82 | D20: 45617 | E20: 5.8167 | F20: 45617 | G20: 109.58 | H20: =G20*E20*1000 -> 637393.99 | I20: 45617 | J20: 5845.7 | K20: =J20*10 -> 58457 | L20: 45617 | M20: 6.92 | N20: 45617 | O20: 6.92 | P20: 45617 | Q20: 6.89 | R20: 45617 | S20: 6.82 | T20: 45617 | U20: 6.81 | V20: 45617 | W20: 6.67 | X20: 45617 | Y20: =NETWORKDAYS(X20,$Z$1,FERIADO!$A$2:$A$408) -> 1544 | Z20: 12.98 | AA20: =$Z$2/(1+Z20/100)^(Y20/252) -> 47343.485 | AB20: =LOG(AA20/AA21) -> 0.00065646295 | AF20: dVaRPort/dw2 | AJ20: 45617 | AK20: =NETWORKDAYS(AJ20,$AJ$1,FERIADO!$A$2:$A$408) -> 531 | AL20: 13.345 | AM20: =$Z$2/(1+AL20/100)^(AK20/252) -> 76800.923 | AN20: =LOG(AM20/AM21) -> 0.00039124307 | AP20: =AB20*$AF$4 -> 0.00032823148 | AQ20: =AN20*$AF$7 -> 0.00011737292 | AR20: =AQ20+AP20 -> 0.0004456044
B21: 45615 | C21: 5926.57 | D21: 45615 | E21: 5.7737 | F21: 45615 | G21: 109.755 | H21: =G21*E21*1000 -> 633692.44 | I21: 45615 | J21: 5798.51 | K21: =J21*10 -> 57985.1 | L21: 45615 | M21: 7.05 | N21: 45615 | O21: 6.96 | P21: 45615 | Q21: 6.95 | R21: 45615 | S21: 6.89 | T21: 45615 | U21: 6.84 | V21: 45615 | W21: 6.73 | X21: 45615 | Y21: =NETWORKDAYS(X21,$Z$1,FERIADO!$A$2:$A$408) -> 1546 | Z21: 12.99 | AA21: =$Z$2/(1+Z21/100)^(Y21/252) -> 47271.976 | AB21: =LOG(AA21/AA22) -> 0.0020974695 | AE21: =AF7*AG7^2+AF4*AG10*AG7*AG4 -> 2.1229359e-05 | AF21: =AE21/$AE$15 -> 0.004224376 | AJ21: 45615 | AK21: =NETWORKDAYS(AJ21,$AJ$1,FERIADO!$A$2:$A$408) -> 533 | AL21: 13.34 | AM21: =$Z$2/(1+AL21/100)^(AK21/252) -> 76731.767 | AN21: =LOG(AM21/AM22) -> 0.0011896591 | AP21: =AB21*$AF$4 -> 0.0010487348 | AQ21: =AN21*$AF$7 -> 0.00035689772 | AR21: =AQ21+AP21 -> 0.0014056325
B22: 45614 | C22: 5900.95 | D22: 45614 | E22: 5.7597 | F22: 45614 | G22: 109.573 | H22: =G22*E22*1000 -> 631107.61 | I22: 45614 | J22: 5777.43 | K22: =J22*10 -> 57774.3 | L22: 45614 | M22: 7.16 | N22: 45614 | O22: 7.02 | P22: 45614 | Q22: 6.99 | R22: 45614 | S22: 6.93 | T22: 45614 | U22: 6.88 | V22: 45614 | W22: 6.75 | X22: 45614 | Y22: =NETWORKDAYS(X22,$Z$1,FERIADO!$A$2:$A$408) -> 1547 | Z22: 13.07 | AA22: =$Z$2/(1+Z22/100)^(Y22/252) -> 47044.222 | AB22: =LOG(AA22/AA23) -> 0.00068354053 | AJ22: 45614 | AK22: =NETWORKDAYS(AJ22,$AJ$1,FERIADO!$A$2:$A$408) -> 534 | AL22: 13.46 | AM22: =$Z$2/(1+AL22/100)^(AK22/252) -> 76521.864 | AN22: =LOG(AM22/AM23) -> 5.5089031e-05 | AP22: =AB22*$AF$4 -> 0.00034177026 | AQ22: =AN22*$AF$7 -> 1.6526709e-05 | AR22: =AQ22+AP22 -> 0.00035829697
B23: 45610 | C23: 5962.02 | D23: 45610 | E23: 5.7879 | F23: 45610 | G23: 109.356 | H23: =G23*E23*1000 -> 632941.59 | I23: 45610 | J23: 5812.57 | K23: =J23*10 -> 58125.7 | L23: 45610 | M23: 7.06 | N23: 45610 | O23: 7.08 | P23: 45610 | Q23: 6.96 | R23: 45610 | S23: 6.92 | T23: 45610 | U23: 6.81 | V23: 45610 | W23: 6.76 | X23: 45610 | Y23: =NETWORKDAYS(X23,$Z$1,FERIADO!$A$2:$A$408) -> 1548 | Z23: 13.09 | AA23: =$Z$2/(1+Z23/100)^(Y23/252) -> 46970.236 | AB23: =LOG(AA23/AA24) -> -0.0026221486 | AE23: MVAR2 | AF23: =AF21*AF7 -> 0.0012673128 | AJ23: 45610 | AK23: =NETWORKDAYS(AJ23,$AJ$1,FERIADO!$A$2:$A$408) -> 535 | AL23: 13.44 | AM23: =$Z$2/(1+AL23/100)^(AK23/252) -> 76512.158 | AN23: =LOG(AM23/AM24) -> -0.00043434041 | AP23: =AB23*$AF$4 -> -0.0013110743 | AQ23: =AN23*$AF$7 -> -0.00013030212 | AR23: =AQ23+AP23 -> -0.0014413764
B24: 45609 | C24: 6006.04 | D24: 45609 | E24: 5.7707 | F24: 45609 | G24: 109.501 | H24: =G24*E24*1000 -> 631897.42 | I24: 45609 | J24: 5840.68 | K24: =J24*10 -> 58406.8 | L24: 45609 | M24: 7.07 | N24: 45609 | O24: 6.98 | P24: 45609 | Q24: 6.99 | R24: 45609 | S24: 6.99 | T24: 45609 | U24: 6.89 | V24: 45609 | W24: 6.81 | X24: 45609 | Y24: =NETWORKDAYS(X24,$Z$1,FERIADO!$A$2:$A$408) -> 1549 | Z24: 12.97 | AA24: =$Z$2/(1+Z24/100)^(Y24/252) -> 47254.687 | AB24: =LOG(AA24/AA25) -> 0.0011558321 | AJ24: 45609 | AK24: =NETWORKDAYS(AJ24,$AJ$1,FERIADO!$A$2:$A$408) -> 536 | AL24: 13.36 | AM24: =$Z$2/(1+AL24/100)^(AK24/252) -> 76588.716 | AN24: =LOG(AM24/AM25) -> 9.364371e-05 | AP24: =AB24*$AF$4 -> 0.00057791605 | AQ24: =AN24*$AF$7 -> 2.8093113e-05 | AR24: =AQ24+AP24 -> 0.00060600916
B25: 45608 | C25: 5996.82 | D25: 45608 | E25: 5.7688 | F25: 45608 | G25: 109.406 | H25: =G25*E25*1000 -> 631141.33 | I25: 45608 | J25: 5780.94 | K25: =J25*10 -> 57809.4 | L25: 45608 | M25: 7 | N25: 45608 | O25: 6.93 | P25: 45608 | Q25: 6.93 | R25: 45608 | S25: 6.88 | T25: 45608 | U25: 6.85 | V25: 45608 | W25: 6.79 | X25: 45608 | Y25: =NETWORKDAYS(X25,$Z$1,FERIADO!$A$2:$A$408) -> 1550 | Z25: 13.01 | AA25: =$Z$2/(1+Z25/100)^(Y25/252) -> 47129.091 | AB25: =LOG(AA25/AA26) -> -0.0042869928 | AE25: Total VaR | AF25: =AF23+AF19 -> 0.0050254426 | AJ25: 45608 | AK25: =NETWORKDAYS(AJ25,$AJ$1,FERIADO!$A$2:$A$408) -> 537 | AL25: 13.345 | AM25: =$Z$2/(1+AL25/100)^(AK25/252) -> 76572.204 | AN25: =LOG(AM25/AM26) -> -0.00097100527 | AP25: =AB25*$AF$4 -> -0.0021434964 | AQ25: =AN25*$AF$7 -> -0.00029130158 | AR25: =AQ25+AP25 -> -0.002434798
B26: 45607 | C26: 6020.89 | D26: 45607 | E26: 5.7974 | F26: 45607 | G26: 109.977 | H26: =G26*E26*1000 -> 637580.66 | I26: 45607 | J26: 5795 | K26: =J26*10 -> 57950 | L26: 45607 | M26: 6.86 | N26: 45607 | O26: 6.82 | P26: 45607 | Q26: 6.82 | R26: 45607 | S26: 6.77 | T26: 45607 | U26: 6.73 | V26: 45607 | W26: 6.63 | X26: 45607 | Y26: =NETWORKDAYS(X26,$Z$1,FERIADO!$A$2:$A$408) -> 1551 | Z26: 12.82 | AA26: =$Z$2/(1+Z26/100)^(Y26/252) -> 47596.614 | AB26: =LOG(AA26/AA27) -> -0.0012149589 | AJ26: 45607 | AK26: =NETWORKDAYS(AJ26,$AJ$1,FERIADO!$A$2:$A$408) -> 538 | AL26: 13.2 | AM26: =$Z$2/(1+AL26/100)^(AK26/252) -> 76743.597 | AN26: =LOG(AM26/AM27) -> -0.00068941132 | AP26: =AB26*$AF$4 -> -0.00060747947 | AQ26: =AN26*$AF$7 -> -0.0002068234 | AR26: =AQ26+AP26 -> -0.00081430287
B27: 45604 | C27: 6014.44 | D27: 45604 | E27: 5.7642 | F27: 45604 | G27: 110.304 | H27: =G27*E27*1000 -> 635814.32 | I27: 45604 | J27: 5779.94 | K27: =J27*10 -> 57799.4 | L27: 45604 | M27: 6.79 | N27: 45604 | O27: 6.77 | P27: 45604 | Q27: 6.76 | R27: 45604 | S27: 6.81 | T27: 45604 | U27: 6.72 | V27: 45604 | W27: 6.62 | X27: 45604 | Y27: =NETWORKDAYS(X27,$Z$1,FERIADO!$A$2:$A$408) -> 1552 | Z27: 12.76 | AA27: =$Z$2/(1+Z27/100)^(Y27/252) -> 47729.954 | AB27: =LOG(AA27/AA28) -> -0.0005051981 | AJ27: 45604 | AK27: =NETWORKDAYS(AJ27,$AJ$1,FERIADO!$A$2:$A$408) -> 539 | AL27: 13.09 | AM27: =$Z$2/(1+AL27/100)^(AK27/252) -> 76865.519 | AN27: =LOG(AM27/AM28) -> -0.00032304568 | AP27: =AB27*$AF$4 -> -0.00025259905 | AQ27: =AN27*$AF$7 -> -9.6913705e-05 | AR27: =AQ27+AP27 -> -0.00034951275
B28: 45603 | C28: 5989.5 | D28: 45603 | E28: 5.6618 | F28: 45603 | G28: 110.372 | H28: =G28*E28*1000 -> 624904.19 | I28: 45603 | J28: 5729.74 | K28: =J28*10 -> 57297.4 | L28: 45603 | M28: 6.85 | N28: 45603 | O28: 6.79 | P28: 45603 | Q28: 6.8 | R28: 45603 | S28: 6.74 | T28: 45603 | U28: 6.72 | V28: 45603 | W28: 6.63 | X28: 45603 | Y28: =NETWORKDAYS(X28,$Z$1,FERIADO!$A$2:$A$408) -> 1553 | Z28: 12.73 | AA28: =$Z$2/(1+Z28/100)^(Y28/252) -> 47785.509 | AB28: =LOG(AA28/AA29) -> 0.0040049632 | AJ28: 45603 | AK28: =NETWORKDAYS(AJ28,$AJ$1,FERIADO!$A$2:$A$408) -> 540 | AL28: 13.025 | AM28: =$Z$2/(1+AL28/100)^(AK28/252) -> 76922.716 | AN28: =LOG(AM28/AM29) -> 0.00037597737 | AP28: =AB28*$AF$4 -> 0.0020024816 | AQ28: =AN28*$AF$7 -> 0.00011279321 | AR28: =AQ28+AP28 -> 0.0021152748
B29: 45602 | C29: 5947.78 | D29: 45602 | E29: 5.7642 | F29: 45602 | G29: 109.489 | H29: =G29*E29*1000 -> 631116.49 | I29: 45602 | J29: 5749.82 | K29: =J29*10 -> 57498.2 | L29: 45602 | M29: 6.92 | N29: 45602 | O29: 6.84 | P29: 45602 | Q29: 6.85 | R29: 45602 | S29: 6.78 | T29: 45602 | U29: 6.78 | V29: 45602 | W29: 6.68 | X29: 45602 | Y29: =NETWORKDAYS(X29,$Z$1,FERIADO!$A$2:$A$408) -> 1554 | Z29: 12.89 | AA29: =$Z$2/(1+Z29/100)^(Y29/252) -> 47346.867 | AB29: =LOG(AA29/AA30) -> -0.00050330824 | AJ29: 45602 | AK29: =NETWORKDAYS(AJ29,$AJ$1,FERIADO!$A$2:$A$408) -> 541 | AL29: 13.045 | AM29: =$Z$2/(1+AL29/100)^(AK29/252) -> 76856.151 | AN29: =LOG(AM29/AM30) -> -0.00061533925 | AP29: =AB29*$AF$4 -> -0.00025165412 | AQ29: =AN29*$AF$7 -> -0.00018460178 | AR29: =AQ29+AP29 -> -0.00043625589
B30: 45601 | C30: 5801.94 | D30: 45601 | E30: 5.784 | F30: 45601 | G30: 110.44 | H30: =G30*E30*1000 -> 638784.96 | I30: 45601 | J30: 5788.47 | K30: =J30*10 -> 57884.7 | L30: 45601 | M30: 6.9 | N30: 45601 | O30: 6.85 | P30: 45601 | Q30: 6.86 | R30: 45601 | S30: 6.8 | T30: 45601 | U30: 6.78 | V30: 45601 | W30: 6.7 | X30: 45601 | Y30: =NETWORKDAYS(X30,$Z$1,FERIADO!$A$2:$A$408) -> 1555 | Z30: 12.86 | AA30: =$Z$2/(1+Z30/100)^(Y30/252) -> 47401.77 | AB30: =LOG(AA30/AA31) -> 0.0028208608 | AJ30: 45601 | AK30: =NETWORKDAYS(AJ30,$AJ$1,FERIADO!$A$2:$A$408) -> 542 | AL30: 12.945 | AM30: =$Z$2/(1+AL30/100)^(AK30/252) -> 76965.124 | AN30: =LOG(AM30/AM31) -> 0.00091378889 | AP30: =AB30*$AF$4 -> 0.0014104304 | AQ30: =AN30*$AF$7 -> 0.00027413667 | AR30: =AQ30+AP30 -> 0.0016845671
B31: 45600 | C31: 5739.37 | D31: 45600 | E31: 5.7892 | F31: 45600 | G31: 110.403 | H31: =G31*E31*1000 -> 639145.05 | I31: 45600 | J31: 5832.14 | K31: =J31*10 -> 58321.4 | L31: 45600 | M31: 6.94 | N31: 45600 | O31: 6.87 | P31: 45600 | Q31: 6.89 | R31: 45600 | S31: 6.85 | T31: 45600 | U31: 6.81 | V31: 45600 | W31: 6.71 | X31: 45600 | Y31: =NETWORKDAYS(X31,$Z$1,FERIADO!$A$2:$A$408) -> 1556 | Z31: 12.97 | AA31: =$Z$2/(1+Z31/100)^(Y31/252) -> 47094.88 | AB31: =LOG(AA31/AA32) -> 0.0040078818 | AJ31: 45600 | AK31: =NETWORKDAYS(AJ31,$AJ$1,FERIADO!$A$2:$A$408) -> 543 | AL31: 13.03 | AM31: =$Z$2/(1+AL31/100)^(AK31/252) -> 76803.353 | AN31: =LOG(AM31/AM32) -> 0.0018685154 | AP31: =AB31*$AF$4 -> 0.0020039409 | AQ31: =AN31*$AF$7 -> 0.00056055463 | AR31: =AQ31+AP31 -> 0.0025644955
B32: 45597 | C32: 5752.67 | D32: 45597 | E32: 5.8067 | F32: 45597 | G32: 109.899 | H32: =G32*E32*1000 -> 638150.52 | I32: 45597 | J32: 5918.49 | K32: =J32*10 -> 59184.9 | L32: 45597 | M32: 7.06 | N32: 45597 | O32: 7.02 | P32: 45597 | Q32: 7.01 | R32: 45597 | S32: 6.96 | T32: 45597 | U32: 6.94 | V32: 45597 | W32: 6.81 | X32: 45597 | Y32: =NETWORKDAYS(X32,$Z$1,FERIADO!$A$2:$A$408) -> 1557 | Z32: 13.13 | AA32: =$Z$2/(1+Z32/100)^(Y32/252) -> 46662.265 | AB32: =LOG(AA32/AA33) -> -0.0043006667 | AJ32: 45597 | AK32: =NETWORKDAYS(AJ32,$AJ$1,FERIADO!$A$2:$A$408) -> 544 | AL32: 13.23 | AM32: =$Z$2/(1+AL32/100)^(AK32/252) -> 76473.623 | AN32: =LOG(AM32/AM33) -> -0.0017372283 | AP32: =AB32*$AF$4 -> -0.0021503334 | AQ32: =AN32*$AF$7 -> -0.0005211685 | AR32: =AQ32+AP32 -> -0.0026715019
B33: 45596 | C33: 5724.93 | D33: 45596 | E33: 5.7773 | F33: 45596 | G33: 110.395 | H33: =G33*E33*1000 -> 637785.03 | I33: 45596 | J33: 5834.65 | K33: =J33*10 -> 58346.5 | L33: 45596 | M33: 6.94 | N33: 45596 | O33: 6.89 | P33: 45596 | Q33: 6.93 | R33: 45596 | S33: 6.9 | T33: 45596 | U33: 6.87 | V33: 45596 | W33: 6.78 | X33: 45596 | Y33: =NETWORKDAYS(X33,$Z$1,FERIADO!$A$2:$A$408) -> 1558 | Z33: 12.94 | AA33: =$Z$2/(1+Z33/100)^(Y33/252) -> 47126.641 | AB33: =LOG(AA33/AA34) -> -0.0026465231 | AJ33: 45596 | AK33: =NETWORKDAYS(AJ33,$AJ$1,FERIADO!$A$2:$A$408) -> 545 | AL33: 12.995 | AM33: =$Z$2/(1+AL33/100)^(AK33/252) -> 76780.139 | AN33: =LOG(AM33/AM34) -> -0.00074760329 | AP33: =AB33*$AF$4 -> -0.0013232616 | AQ33: =AN33*$AF$7 -> -0.00022428099 | AR33: =AQ33+AP33 -> -0.0015475425
B34: 45595 | C34: 5832.02 | D34: 45595 | E34: 5.7795 | F34: 45595 | G34: 110.408 | H34: =G34*E34*1000 -> 638103.04 | I34: 45595 | J34: 5806.54 | K34: =J34*10 -> 58065.4 | L34: 45595 | M34: 6.9 | N34: 45595 | O34: 6.86 | P34: 45595 | Q34: 6.88 | R34: 45595 | S34: 6.87 | T34: 45595 | U34: 6.87 | V34: 45595 | W34: 6.81 | X34: 45595 | Y34: =NETWORKDAYS(X34,$Z$1,FERIADO!$A$2:$A$408) -> 1559 | Z34: 12.82 | AA34: =$Z$2/(1+Z34/100)^(Y34/252) -> 47414.7 | AB34: =LOG(AA34/AA35) -> 0.0016372954 | AJ34: 45595 | AK34: =NETWORKDAYS(AJ34,$AJ$1,FERIADO!$A$2:$A$408) -> 546 | AL34: 12.88 | AM34: =$Z$2/(1+AL34/100)^(AK34/252) -> 76912.424 | AN34: =LOG(AM34/AM35) -> 0.00045930334 | AP34: =AB34*$AF$4 -> 0.00081864772 | AQ34: =AN34*$AF$7 -> 0.000137791 | AR34: =AQ34+AP34 -> 0.00095643873
B35: 45594 | C35: 5869.01 | D35: 45594 | E35: 5.7134 | F35: 45594 | G35: 110.855 | H35: =G35*E35*1000 -> 633358.96 | I35: 45594 | J35: 5803.52 | K35: =J35*10 -> 58035.2 | L35: 45594 | M35: 6.87 | N35: 45594 | O35: 6.83 | P35: 45594 | Q35: 6.88 | R35: 45594 | S35: 6.88 | T35: 45594 | U35: 6.87 | V35: 45594 | W35: 6.83 | X35: 45594 | Y35: =NETWORKDAYS(X35,$Z$1,FERIADO!$A$2:$A$408) -> 1560 | Z35: 12.88 | AA35: =$Z$2/(1+Z35/100)^(Y35/252) -> 47236.282 | AB35: =LOG(AA35/AA36) -> -0.0016984786 | AJ35: 45594 | AK35: =NETWORKDAYS(AJ35,$AJ$1,FERIADO!$A$2:$A$408) -> 547 | AL35: 12.91 | AM35: =$Z$2/(1+AL35/100)^(AK35/252) -> 76831.125 | AN35: =LOG(AM35/AM36) -> -0.00054383562 | AP35: =AB35*$AF$4 -> -0.00084923931 | AQ35: =AN35*$AF$7 -> -0.00016315069 | AR35: =AQ35+AP35 -> -0.00101239
B36: 45593 | C36: 5854.31 | D36: 45593 | E36: 5.6982 | F36: 45593 | G36: 110.68 | H36: =G36*E36*1000 -> 630676.78 | I36: 45593 | J36: 5752.68 | K36: =J36*10 -> 57526.8 | L36: 45593 | M36: 6.75 | N36: 45593 | O36: 6.73 | P36: 45593 | Q36: 6.8 | R36: 45593 | S36: 6.82 | T36: 45593 | U36: 6.83 | V36: 45593 | W36: 6.8 | X36: 45593 | Y36: =NETWORKDAYS(X36,$Z$1,FERIADO!$A$2:$A$408) -> 1561 | Z36: 12.8 | AA36: =$Z$2/(1+Z36/100)^(Y36/252) -> 47421.38 | AB36: =LOG(AA36/AA37) -> -0.00026976022 | AJ36: 45593 | AK36: =NETWORKDAYS(AJ36,$AJ$1,FERIADO!$A$2:$A$408) -> 548 | AL36: 12.82 | AM36: =$Z$2/(1+AL36/100)^(AK36/252) -> 76927.396 | AN36: =LOG(AM36/AM37) -> 0.00033366736 | AP36: =AB36*$AF$4 -> -0.00013488011 | AQ36: =AN36*$AF$7 -> 0.00010010021 | AR36: =AQ36+AP36 -> -3.4779902e-05
B37: 45590 | C37: 5830.56 | D37: 45590 | E37: 5.6963 | F37: 45590 | G37: 111.008 | H37: =G37*E37*1000 -> 632334.87 | I37: 45590 | J37: 5752.68 | K37: =J37*10 -> 57526.8 | L37: 45590 | M37: 6.67 | N37: 45590 | O37: 6.67 | P37: 45590 | Q37: 6.77 | R37: 45590 | S37: 6.8 | T37: 45590 | U37: 6.77 | V37: 45590 | W37: 6.76 | X37: 45590 | Y37: =NETWORKDAYS(X37,$Z$1,FERIADO!$A$2:$A$408) -> 1562 | Z37: 12.78 | AA37: =$Z$2/(1+Z37/100)^(Y37/252) -> 47450.845 | AB37: =LOG(AA37/AA38) -> -0.0031385946 | AJ37: 45590 | AK37: =NETWORKDAYS(AJ37,$AJ$1,FERIADO!$A$2:$A$408) -> 549 | AL37: 12.835 | AM37: =$Z$2/(1+AL37/100)^(AK37/252) -> 76868.315 | AN37: =LOG(AM37/AM38) -> -0.00096868296 | AP37: =AB37*$AF$4 -> -0.0015692973 | AQ37: =AN37*$AF$7 -> -0.00029060489 | AR37: =AQ37+AP37 -> -0.0018599022
... B699: 44628 | C699: 4542.31 | D699: 44628 | E699: 5.0897 | F699: 44624 | G699: 128.454 | H699: =G699*E699*1000 -> 653792.32 | I699: 44628 | J699: 6007.28 | K699: =J699*10 -> 60072.8 | L699: 44628 | M699: 5.57 | N699: 44628 | O699: 5.57 | P699: 44628 | Q699: 5.65 | R699: 44628 | S699: 5.58 | T699: 44573 | U699: 5.29 | V699: 44627 | W699: 5.61 | X699: 44628 | Y699: =NETWORKDAYS(X699,$Z$1,FERIADO!$A$2:$A$408) -> 2226 | Z699: 12.41 | AA699: =$Z$2/(1+Z699/100)^(Y699/252) -> 35581.394 | AB699: =LOG(AA699/AA700) -> -0.0062910122 | AJ699: 44628 | AK699: =NETWORKDAYS(AJ699,$AJ$1,FERIADO!$A$2:$A$408) -> 1213 | AL699: 12.26 | AM699: =$Z$2/(1+AL699/100)^(AK699/252) -> 57311.553 | AN699: =LOG(AM699/AM700) -> -0.0031580576 | AP699: =AB699*$AF$4 -> -0.0031455061 | AQ699: =AN699*$AF$7 -> -0.00094741727 | AR699: =AQ699+AP699 -> -0.0040929234
B700: 44627 | C700: 4579.14 | D700: 44627 | E700: 5.0573 | F700: 44623 | G700: 127.486 | H700: =G700*E700*1000 -> 644734.95 | I700: 44627 | J700: 6076.87 | K700: =J700*10 -> 60768.7 | L700: 44627 | M700: 5.48 | N700: 44627 | O700: 5.49 | P700: 44627 | Q700: 5.57 | R700: 44627 | S700: 5.6 | V700: 44624 | W700: 5.48 | X700: 44627 | Y700: =NETWORKDAYS(X700,$Z$1,FERIADO!$A$2:$A$408) -> 2227 | Z700: 12.22 | AA700: =$Z$2/(1+Z700/100)^(Y700/252) -> 36100.563 | AB700: =LOG(AA700/AA701) -> -0.012138853 | AJ700: 44627 | AK700: =NETWORKDAYS(AJ700,$AJ$1,FERIADO!$A$2:$A$408) -> 1214 | AL700: 12.08 | AM700: =$Z$2/(1+AL700/100)^(AK700/252) -> 57729.824 | AN700: =LOG(AM700/AM701) -> -0.006727371 | AP700: =AB700*$AF$4 -> -0.0060694265 | AQ700: =AN700*$AF$7 -> -0.0020182113 | AR700: =AQ700+AP700 -> -0.0080876378
B701: 44624 | C701: 4719.78 | D701: 44624 | E701: 5.0752 | F701: 44622 | G701: 127.323 | H701: =G701*E701*1000 -> 646189.69 | I701: 44624 | J701: 6014.95 | K701: =J701*10 -> 60149.5 | L701: 44624 | M701: 5.44 | N701: 44624 | O701: 5.46 | P701: 44624 | Q701: 5.53 | R701: 44624 | S701: 5.54 | V701: 44623 | W701: 5.47 | X701: 44624 | Y701: =NETWORKDAYS(X701,$Z$1,FERIADO!$A$2:$A$408) -> 2228 | Z701: 11.86 | AA701: =$Z$2/(1+Z701/100)^(Y701/252) -> 37123.834 | AB701: =LOG(AA701/AA702) -> -0.0046176645 | AJ701: 44624 | AK701: =NETWORKDAYS(AJ701,$AJ$1,FERIADO!$A$2:$A$408) -> 1215 | AL701: 11.71 | AM701: =$Z$2/(1+AL701/100)^(AK701/252) -> 58631.041 | AN701: =LOG(AM701/AM702) -> -0.0037523977 | AP701: =AB701*$AF$4 -> -0.0023088323 | AQ701: =AN701*$AF$7 -> -0.0011257193 | AR701: =AQ701+AP701 -> -0.0034345516
...

Sheet FERIADO
A1: HOLIDAYS BZ
A2: 44197
A3: 44242
A4: 44243
A5: 44288
A6: 44307
A7: 44317
A8: 44350
A9: 44446
A10: 44481
A11: 44502
A12: 44515
A13: 44555
... A408: 21977
