Workbook
Name contrato: 'Base de dados'!$E$1
Name data_ref: 'Base de dados'!$B$1
Name data_ref_ant1: 'Base de dados'!$B$4
Name data_ref_ant2: 'Base de dados'!$B$5
Name data_ref_post1: 'Base de dados'!$B$2
Name data_ref_post2: 'Base de dados'!$B$3
Name DCL: 'Base de dados'!$M$3
Name di: 'Base de dados'!$E$2
Name di_dia: 'Base de dados'!$E$3
Name feriados: Feriados!$A$1:$A$1264
Name pl: PnL!$U$2
Name ptax: 'Base de dados'!$M$1
Name ptax_ant: 'Base de dados'!$M$2
Name rs_dap: 'Base de dados'!$J$5

Sheet Base de dados
A1: DATA_REF | B1: 45958 | D1: Notional contrato | E1: 100000 | G1: R$ PT | H1: 0.00025 | I1: NI IPCA Ref | J1: =VLOOKUP("15/0"&MONTH(H2)-1&"/"&YEAR(H2),NI_IPCA!$A$1:$B$551,2,0) -> 7359.06 | L1: PTAX | M1: =VLOOKUP(data_ref,$A$9:$D$32,4,0) -> 5.369
A2: DU+1 | B2: =WORKDAY(data_ref,1,feriados) -> 45959 | D2: cdi | E2: 14.15 | G2: IPCA_Ref | H2: =IF(DAY(data_ref)>15,"15/"&MONTH(data_ref)&"/"&YEAR(data_ref),"15/"&MONTH(data_ref)-1&"/"&YEAR(data_ref)) -> 15/10/2025 | I2: Projeção ANBIMA | J2: 0.67 | L2: PTAX T-1 | M2: =VLOOKUP(data_ref_ant1,$A$9:$D$32,4,0) -> 5.3744
A3: DU+2 | B3: =WORKDAY(data_ref,2,feriados) -> 45960 | D3: cdi_dia | E3: =((1+E2%)^(1/252)-1)*100 -> 0.05253093 | G3: Próximo | H3: ="15/"&MONTH(H2)+1&"/"&YEAR(H2) -> 15/11/2025 | L3: DCL | M3: 5.3588
A4: DU-1 | B4: =WORKDAY(data_ref,-1,feriados) -> 45957 | E4: 15 | G4: DU desde | H4: =NETWORKDAYS(H2,data_ref,feriados)-1 -> 9 | I4: IPCA Pro Rata | J4: =J1*(J2/100+1)^((H4)/H5) -> 7379.1907 | L4: Spot BMF T2 | M4: 5,3616
A5: DU-2 | B5: =WORKDAY(data_ref,-2,feriados) -> 45954 | G5: DU entre | H5: =NETWORKDAYS(H2,H3,feriados)-1 -> 22 | I5: Valor Ponto (R$) | J5: =J4*H1 -> 1.8447977 | L5: Spot BMF T1 | M5: 5,3593
A8: PTAX BC | G8: DI1 | X8: DAP | AP8: DDI | BG8: FRC
A9: Data | B9: Tipo | C9: Cotações em Real1/ | G9: Vencimento | H9: Contratos em Aberto | I9: Negócios Realizados | J9: Contratos Negociados | K9: Volume | L9: Ajuste Anterior | M9: Preço de Abertura | N9: Preço Mínimo | O9: Preço Máximo | P9: Preço Médio | Q9: Último Preço | R9: Ajuste | S9: Variação em Pontos | T9: Última Oferta de Compra | U9: Última Oferta de Venda | X9: Vencimento | Y9: Contratos em Aberto | Z9: Negócios Realizados | AA9: Contratos Negociados | AB9: Volume | AC9: Ajuste Anterior | AD9: Preço de Abertura | AE9: Preço Mínimo | AF9: Preço Máximo | AG9: Preço Médio | AH9: Último Preço | AI9: Ajuste | AJ9: Variação em Pontos | AK9: Última Oferta de Compra | AL9: Última Oferta de Venda | AP9: Vencimento | AQ9: Contratos em Aberto | AR9: Negócios Realizados | AS9: Contratos Negociados | AT9: Volume | AU9: Ajuste Anterior | AV9: Preço de Abertura | AW9: Preço Mínimo | AX9: Preço Máximo | AY9: Preço Médio | AZ9: Último Preço | BA9: Ajuste | BB9: Variação em Pontos | BC9: Última Oferta de Compra | BD9: Última Oferta de Venda | BG9: Vencimento | BH9: Negócios Realizados | BI9: Contratos Negociados | BJ9: Volume | BK9: Preço de Abertura | BL9: Preço Mínimo | BM9: Preço Máximo | BN9: Preço Médio | BO9: Último Preço | BP9: Ajuste de Referência | BQ9: Variação em Pontos | BR9: Última Oferta de Compra | BS9: Última Oferta de Venda
C10: Compra | D10: Venda | G10: F26 | H10: 4293547 | I10: 3609 | J10: 188316 | K10: 18370438581 | L10: 97551.22 | M10: 14.9 | N10: 14.89 | O10: 14.9 | P10: 14.89 | Q10: 14.89 | R10: 97551.05 | S10: -0,17↓ | T10: 14.89 | U10: 14.9 | X10: F26 | Y10: 66207 | Z10: 11 | AA10: 688 | AB10: 123840048 | AC10: 97792.44 | AD10: 10.9 | AE10: 10.9 | AF10: 10.9 | AG10: 10.9 | AH10: 10.9 | AI10: 97767.28 | AJ10: -25,16↓ | AK10: 10.85 | AL10: 11.05 | AP10: F26 | AQ10: 989623 | AR10: 1 | AS10: 380 | AT10: 100858080 | AU10: 98925.22 | AV10: 6.79 | AW10: 6.79 | AX10: 6.79 | AY10: 6.79 | AZ10: 6.79 | BA10: 98648.29 | BB10: -276,93↓ | BC10: - | BD10: - | BG10: F26 | BH10: 51 | BI10: 74901 | BJ10: 9053459808 | BK10: 5.48 | BL10: 5.44 | BM10: 5.53 | BN10: 5.44 | BO10: 5.51 | BP10: 5.44 | BQ10: -0,04↓ | BR10: - | BS10: -
A11: 45930 | B11: A | C11: 5.318 | D11: 5.3186 | G11: F27 | H11: 5690218 | I11: 12644 | J11: 249338 | K11: 21434284584 | L11: 85989.57 | M11: 13.83 | N11: 13.82 | O11: 13.86 | P11: 13.84 | Q11: 13.82 | R11: 85966.95 | S11: -22,62↓ | T11: 13.82 | U11: 13.83 | X11: F27 | Y11: 8472 | Z11: - | AA11: - | AB11: - | AC11: 89870.99 | AD11: - | AE11: - | AF11: - | AG11: - | AH11: - | AI11: 89884.31 | AJ11: 13,32↑ | AK11: - | AL11: - | AP11: F27 | AQ11: 203897 | AR11: 1 | AS11: 42 | AT11: 10626710 | AU11: 94392.35 | AV11: 5.16 | AW11: 5.16 | AX11: 5.16 | AY11: 5.16 | AZ11: 5.16 | BA11: 94111.58 | BB11: -280,77↓ | BC11: - | BD11: - | BG11: F27 | BH11: 13 | BI11: 3776 | BJ11: 445629333 | BK11: 4.82 | BL11: 4.82 | BM11: 4.85 | BN11: 4.84 | BO11: 4.85 | BP11: 4.85 | BQ11: 0,03↑ | BR11: - | BS11: -
A12: 45931 | B12: A | C12: 5.3202 | D12: 5.3208 | G12: F28 | H12: 3449288 | I12: 16835 | J12: 264327 | K12: 20240884462 | L12: 76655.83 | M12: 13.1 | N12: 13.1 | O12: 13.15 | P12: 13.13 | Q12: 13.12 | R12: 76583.59 | S12: -72,24↓ | T12: 13.12 | U12: 13.13 | X12: G26 | Y12: - | Z12: - | AA12: - | AB12: - | AC12: 97069.2 | AD12: - | AE12: - | AF12: - | AG12: - | AH12: - | AI12: 97046.26 | AJ12: -22,94↓ | AK12: 10.09 | AL12: 10.53 | AP12: F28 | AQ12: 135601 | AR12: - | AS12: - | AT12: - | AU12: 90442.51 | AV12: - | AW12: - | AX12: - | AY12: - | AZ12: - | BA12: 90146.96 | BB12: -295,55↓ | BC12: - | BD12: - | BG12: F28 | BH12: 9 | BI12: 2080 | BJ12: 239987734 | BK12: 4.72 | BL12: 4.72 | BM12: 4.72 | BN12: 4.72 | BO12: 4.72 | BP12: 4.72 | BQ12: 0 | BR12: 4.71 | BS12: -
A13: 45932 | B13: A | C13: 5.3443 | D13: 5.3449 | G13: F29 | H13: 3437018 | I13: 18024 | J13: 165809 | K13: 11261721804 | L13: 68035.22 | M13: 13.05 | N13: 13.03 | O13: 13.1 | P13: 13.08 | Q13: 13.08 | R13: 67928.58 | S13: -106,64↓ | T13: 13.08 | U13: 13.08 | X13: H26 | Y13: - | Z13: - | AA13: - | AB13: - | AC13: 96583.04 | AD13: - | AE13: - | AF13: - | AG13: - | AH13: - | AI13: 96563.48 | AJ13: -19,56↓ | AK13: 9.5 | AL13: 9.94 | AP13: F29 | AQ13: 78560 | AR13: - | AS13: - | AT13: - | AU13: 86587.16 | AV13: - | AW13: - | AX13: - | AY13: - | AZ13: - | BA13: 86266.84 | BB13: -320,32↓ | BC13: - | BD13: - | BG13: F29 | BH13: 14 | BI13: 1942 | BJ13: 219105276 | BK13: 4.79 | BL13: 4.76 | BM13: 4.79 | BN13: 4.76 | BO13: 4.76 | BP13: 4.76 | BQ13: -0,03↓ | BR13: - | BS13: -
A14: 45933 | B14: A | C14: 5.3492 | D14: 5.3498 | G14: F30 | H14: 1120661 | I14: 8891 | J14: 43757 | K14: 2617971005 | L14: 59976.14 | M14: 13.19 | N14: 13.18 | O14: 13.25 | P14: 13.23 | Q14: 13.23 | R14: 59823.72 | S14: -152,42↓ | T14: 13.23 | U14: 13.24 | X14: J26 | Y14: - | Z14: - | AA14: - | AB14: - | AC14: 95836.88 | AD14: - | AE14: - | AF14: - | AG14: - | AH14: - | AI14: 95819.91 | AJ14: -16,97↓ | AK14: 9.5 | AL14: 9.94 | AP14: F30 | AQ14: 62600 | AR14: - | AS14: - | AT14: - | AU14: 82701.08 | AV14: - | AW14: - | AX14: - | AY14: - | AZ14: - | BA14: 82407.41 | BB14: -293,67↓ | BC14: - | BD14: - | BG14: F30 | BH14: 13 | BI14: 2394 | BJ14: 263537245 | BK14: 4.94 | BL14: 4.9 | BM14: 4.94 | BN14: 4.9 | BO14: 4.9 | BP14: 4.9 | BQ14: -0,04↓ | BR14: 4.9 | BS14: -
A15: 45936 | B15: A | C15: 5.322 | D15: 5.3226 | G15: F31 | H15: 1807011 | I15: 10258 | J15: 127860 | K15: 6716635417 | L15: 52700.41 | M15: 13.32 | N15: 13.3 | O15: 13.38 | P15: 13.36 | Q15: 13.38 | R15: 52518.67 | S15: -181,74↓ | T15: 13.36 | U15: 13.38 | X15: K27 | Y15: 316374 | Z15: 55 | AA15: 6989 | AB15: 1130896749 | AC15: 87835.65 | AD15: 8.86 | AE15: 8.79 | AF15: 8.87 | AG15: 8.79 | AH15: 8.79 | AI15: 87893.14 | AJ15: 57,49↑ | AK15: - | AL15: 8.83 | AP15: F31 | AQ15: 70843 | AR15: - | AS15: - | AT15: - | AU15: 78710.39 | AV15: - | AW15: - | AX15: - | AY15: - | AZ15: - | BA15: 78420.25 | BB15: -290,14↓ | BC15: - | BD15: - | BG15: F31 | BH15: 2 | BI15: 286 | BJ15: 30616505 | BK15: 5.17 | BL15: 5.12 | BM15: 5.17 | BN15: 5.13 | BO15: 5.12 | BP15: 5.12 | BQ15: -0,05↓ | BR15: - | BS15: -
A16: 45937 | B16: A | C16: 5.3357 | D16: 5.3363 | G16: F32 | H16: 1291206 | I16: 1831 | J16: 70977 | K16: 3269087249 | L16: 46235.54 | M16: 13.43 | N16: 13.43 | O16: 13.49 | P16: 13.47 | Q16: 13.48 | R16: 46048.47 | S16: -187,07↓ | T16: 13.47 | U16: 13.5 | X16: K29 | Y16: 198198 | Z16: 60 | AA16: 6762 | AB16: 952510486 | AC16: 76456.21 | AD16: 7.96 | AE16: 7.9 | AF16: 7.98 | AG16: 7.92 | AH16: 7.91 | AI16: 76540.36 | AJ16: 84,15↑ | AK16: - | AL16: 7.97 | AP16: F32 | AQ16: 45338 | AR16: - | AS16: - | AT16: - | AU16: 74590.55 | AV16: - | AW16: - | AX16: - | AY16: - | AZ16: - | BA16: 74411.46 | BB16: -179,09↓ | BC16: - | BD16: - | BG16: F32 | BH16: 7 | BI16: 384 | BJ16: 16385402 | BK16: 5.44 | BL16: 5.41 | BM16: 5.44 | BN16: 5.41 | BO16: 5.41 | BP16: 5.41 | BQ16: -0,03↓ | BR16: - | BS16: -
A17: 45938 | B17: A | C17: 5.3421 | D17: 5.3427 | G17: F33 | H17: 599882 | I17: 3980 | J17: 20595 | K17: 833888595 | L17: 40656.76 | M17: 13.47 | N17: 13.46 | O17: 13.53 | P17: 13.51 | Q17: 13.53 | R17: 40478.71 | S17: -178,05↓ | T17: 13.51 | U17: 13.54 | X17: K33 | Y17: 198742 | Z17: 48 | AA17: 4418 | AB17: 469216368 | AC17: 57591.78 | AD17: 7.64 | AE17: 7.6 | AF17: 7.64 | AG17: 7.61 | AH17: 7.6 | AI17: 57730.85 | AJ17: 139,07↑ | AK17: 7.58 | AL17: 7.66 | AP17: F33 | AQ17: 28220 | AR17: - | AS17: - | AT17: - | AU17: 70716.03 | AV17: - | AW17: - | AX17: - | AY17: - | AZ17: - | BA17: 70441.32 | BB17: -274,71↓ | BC17: - | BD17: - | BG17: F33 | BH17: 2 | BI17: 342 | BJ17: 14144148 | BK17: 5.69 | BL17: 5.69 | BM17: 5.69 | BN17: 5.69 | BO17: 5.69 | BP17: 5.66 | BQ17: -0,03↓ | BR17: - | BS17: -
A18: 45939 | B18: A | C18: 5.3532 | D18: 5.3538 | G18: F34 | H18: 272158 | I18: 370 | J18: 1478 | K18: 52693547 | L18: 35825.41 | M18: 13.48 | N18: 13.48 | O18: 13.54 | P18: 13.52 | Q18: 13.54 | R18: 35652.06 | S18: -173,35↓ | T18: 13.52 | U18: 13.59 | X18: K35 | Y18: 416265 | Z18: 105 | AA18: 21904 | AB18: 2040284776 | AC18: 50575.61 | AD18: 7.46 | AE18: 7.42 | AF18: 7.48 | AG18: 7.45 | AH18: 7.46 | AI18: 50556.27 | AJ18: -19,34↓ | AK18: 7.42 | AL18: 7.49 | AP18: F34 | AQ18: 36930 | AR18: - | AS18: - | AT18: - | AU18: 66865.73 | AV18: - | AW18: - | AX18: - | AY18: - | AZ18: - | BA18: 66785.28 | BB18: -80,45↓ | BC18: - | BD18: - | BG18: F34 | BH18: 2 | BI18: 334 | BJ18: 13363755 | BK18: 5.97 | BL18: 5.97 | BM18: 5.97 | BN18: 5.97 | BO18: 5.97 | BP18: 5.95 | BQ18: -0,02↓ | BR18: - | BS18: -
A19: 45940 | B19: A | C19: 5.444 | D19: 5.4446 | G19: F35 | H19: 768021 | I19: 3443 | J19: 28396 | K19: 893178331 | L19: 31606.51 | M19: 13.5 | N19: 13.48 | O19: 13.56 | P19: 13.53 | Q19: 13.56 | R19: 31437.86 | S19: -168,65↓ | T19: 13.53 | U19: 13.57 | X19: K45 | Y19: 19051 | Z19: 4 | AA19: 131 | AB19: 6346295 | AC19: 25831.71 | AD19: 7.12 | AE19: 7.12 | AF19: 7.12 | AG19: 7.12 | AH19: 7.12 | AI19: 26312.97 | AJ19: 481,26↑ | AK19: - | AL19: - | AP19: F35 | AQ19: 37620 | AR19: - | AS19: - | AT19: - | AU19: 63173.92 | AV19: - | AW19: - | AX19: - | AY19: - | AZ19: - | BA19: 63102.39 | BB19: -71,53↓ | BC19: - | BD19: - | BG19: F35 | BH19: 3 | BI19: 2758 | BJ19: 106595309 | BK19: 6.26 | BL19: 6.26 | BM19: 6.26 | BN19: 6.26 | BO19: 6.26 | BP19: 6.24 | BQ19: -0,02↓ | BR19: - | BS19: -
A20: 45943 | B20: A | C20: 5.4623 | D20: 5.4629 | G20: F36 | H20: 65504 | I20: 152 | J20: 824 | K20: 22957142 | L20: 27993.52 | M20: 13.49 | N20: 13.48 | O20: 13.52 | P20: 13.48 | Q20: 13.52 | R20: 27823.12 | S20: -170,40↓ | T20: - | U20: - | X20: K55 | Y20: 2456 | Z20: - | AA20: - | AB20: - | AC20: 13443.03 | AD20: - | AE20: - | AF20: - | AG20: - | AH20: - | AI20: 13419.29 | AJ20: -23,74↓ | AK20: - | AL20: - | AP20: F36 | AQ20: 16210 | AR20: - | AS20: - | AT20: - | AU20: 59690.29 | AV20: - | AW20: - | AX20: - | AY20: - | AZ20: - | BA20: 59630.8 | BB20: -59,49↓ | BC20: - | BD20: - | BG20: F36 | BH20: 2 | BI20: 176 | BJ20: 6575496 | BK20: 6.52 | BL20: 6.52 | BM20: 6.52 | BN20: 6.52 | BO20: 6.52 | BP20: 6.52 | BQ20: -0,02↓ | BR20: - | BS20: -
A21: 45944 | B21: A | C21: 5.4976 | D21: 5.4982 | G21: F37 | H21: 57135 | I21: 43 | J21: 568 | K21: 13944869 | L21: 24714.94 | M21: 13.5 | N21: 13.47 | O21: 13.5 | P21: 13.48 | Q21: 13.48 | R21: 24559.29 | S21: -155,65↓ | T21: 13.47 | U21: 13.51 | X21: Q26 | Y21: 340668 | Z21: 57 | AA21: 12670 | AB21: 2159861587 | AC21: 92591.82 | AD21: 10.15 | AE21: 10.11 | AF21: 10.15 | AG21: 10.13 | AH21: 10.14 | AI21: 92589.03 | AJ21: -2,79↓ | AK21: - | AL21: 10.14 | AP21: F37 | AQ21: 22220 | AR21: - | AS21: - | AT21: - | AU21: 56352.14 | AV21: - | AW21: - | AX21: - | AY21: - | AZ21: - | BA21: 56296.79 | BB21: -55,35↓ | BC21: - | BD21: - | BG21: F37 | BH21: 1 | BI21: 313 | BJ21: 11268650 | BK21: 6.82 | BL21: 6.82 | BM21: 6.82 | BN21: 6.82 | BO21: 6.82 | BP21: 6.81 | BQ21: -0,01↓ | BR21: - | BS21: -
A22: 45945 | B22: A | C22: 5.4458 | D22: 5.4464 | G22: F38 | H22: 43856 | I22: 28 | J22: 69 | K22: 1503522 | L22: 21932.43 | M22: 13.43 | N22: 13.43 | O22: 13.43 | P22: 13.43 | Q22: 13.43 | R22: 21791.35 | S22: -141,08↓ | T22: - | U22: - | X22: Q28 | Y22: 326268 | Z22: 62 | AA22: 10130 | AB22: 1499629911 | AC22: 80362.69 | AD22: 8.2 | AE22: 8.14 | AF22: 8.2 | AG22: 8.15 | AH22: 8.14 | AI22: 80447.85 | AJ22: 85,16↑ | AK22: 8.14 | AL22: - | AP22: F38 | AQ22: 2820 | AR22: - | AS22: - | AT22: - | AU22: 53332.6 | AV22: - | AW22: - | AX22: - | AY22: - | AZ22: - | BA22: 53249.28 | BB22: -83,32↓ | BC22: - | BD22: - | BG22: F38 | BH22: - | BI22: - | BJ22: - | BK22: - | BL22: - | BM22: - | BN22: - | BO22: - | BP22: 7.06 | BQ22: -0,01↓ | BR22: - | BS22: -
A23: 45946 | B23: A | C23: 5.4348 | D23: 5.4354 | G23: F39 | H23: 31205 | I23: 6 | J23: 18 | K23: 346846 | L23: 19455.02 | M23: 13.4 | N23: 13.4 | O23: 13.41 | P23: 13.4 | Q23: 13.41 | R23: 19319.61 | S23: -135,41↓ | T23: - | U23: - | X23: Q30 | Y23: 394224 | Z23: 192 | AA23: 35677 | AB23: 4596524630 | AC23: 69916.39 | AD23: 7.82 | AE23: 7.77 | AF23: 7.82 | AG23: 7.79 | AH23: 7.78 | AI23: 70014.08 | AJ23: 97,69↑ | AK23: 7.78 | AL23: 7.81 | AP23: F39 | AQ23: 2860 | AR23: - | AS23: - | AT23: - | AU23: 50366.92 | AV23: - | AW23: - | AX23: - | AY23: - | AZ23: - | BA23: 50291.38 | BB23: -75,54↓ | BC23: - | BD23: - | BG23: F39 | BH23: - | BI23: - | BJ23: - | BK23: - | BL23: - | BM23: - | BN23: - | BO23: - | BP23: 7.35 | BQ23: 0 | BR23: - | BS23: -
A24: 45947 | B24: A | C24: 5.4384 | D24: 5.439 | G24: F40 | H24: 48121 | I24: 3 | J24: 13 | K24: 222363 | L24: 17197.96 | M24: 13.36 | N24: 13.35 | O24: 13.36 | P24: 13.35 | Q24: 13.35 | R24: 17069.24 | S24: -128,72↓ | T24: - | U24: - | X24: Q32 | Y24: 282640 | Z24: 97 | AA24: 18061 | AB24: 2016272469 | AC24: 60615.94 | AD24: 7.7 | AE24: 7.67 | AF24: 7.71 | AG24: 7.68 | AH24: 7.68 | AI24: 60707.49 | AJ24: 91,55↑ | AK24: 7.68 | AL24: - | AP24: F40 | AQ24: 4010 | AR24: - | AS24: - | AT24: - | AU24: 47584 | AV24: - | AW24: - | AX24: - | AY24: - | AZ24: - | BA24: 47512.5 | BB24: -71,50↓ | BC24: - | BD24: - | BG24: F40 | BH24: 1 | BI24: 148 | BJ24: 4773786 | BK24: 7.64 | BL24: 7.64 | BM24: 7.64 | BN24: 7.64 | BO24: 7.64 | BP24: 7.64 | BQ24: 0 | BR24: - | BS24: -
A25: 45950 | B25: A | C25: 5.3765 | D25: 5.3771 | G25: G26 | H25: 453905 | I25: 30 | J25: 20540 | K25: 1980690208 | L25: 96432.18 | M25: 14.89 | N25: 14.88 | O25: 14.89 | P25: 14.89 | Q25: 14.88 | R25: 96431.02 | S25: -1,16↓ | T25: 14.88 | U25: 14.89 | X25: Q40 | Y25: 123760 | Z25: 54 | AA25: 5010 | AB25: 327485118 | AC25: 35474.44 | AD25: 7.29 | AE25: 7.28 | AF25: 7.3 | AG25: 7.29 | AH25: 7.3 | AI25: 35484.99 | AJ25: 10,55↑ | AK25: 7.25 | AL25: 7.35 | AP25: G26 | AQ25: 310879 | AR25: 1 | AS25: 26 | AT25: 6869189.9 | AU25: 98497.55 | AV25: 6.35 | AW25: 6.35 | AX25: 6.35 | AY25: 6.35 | AZ25: 6.35 | BA25: 98222.84 | BB25: -274,71↓ | BC25: - | BD25: - | BG25: G26 | BH25: 71 | BI25: 37372 | BJ25: 1852103583 | BK25: 5.33 | BL25: 5.31 | BM25: 5.33 | BN25: 5.32 | BO25: 5.31 | BP25: 5.32 | BQ25: -0,03↓ | BR25: - | BS25: -
A26: 45951 | B26: A | C26: 5.3842 | D26: 5.3848 | G26: H26 | H26: 380513 | I26: 10 | J26: 3468 | K26: 331149819 | L26: 95488.42 | M26: 14.86 | N26: 14.86 | O26: 14.86 | P26: 14.86 | Q26: 14.86 | R26: 95487.72 | S26: -0,70↓ | T26: 14.85 | U26: 14.86 | X26: Q50 | Y26: 3929 | Z26: - | AA26: - | AB26: - | AC26: 18347.46 | AD26: - | AE26: - | AF26: - | AG26: - | AH26: - | AI26: 18323.35 | AJ26: -24,11↓ | AK26: - | AL26: - | AP26: H26 | AQ26: 161257 | AR26: - | AS26: - | AT26: - | AU26: 98128.81 | AV26: - | AW26: - | AX26: - | AY26: - | AZ26: - | BA26: 97854.01 | BB26: -274,80↓ | BC26: - | BD26: - | BG26: H26 | BH26: 50 | BI26: 38703 | BJ26: 1914405504 | BK26: 5.25 | BL26: 5.22 | BM26: 5.31 | BN26: 5.23 | BO26: 5.24 | BP26: 5.22 | BQ26: -0,04↓ | BR26: - | BS26: 5.22
A27: 45952 | B27: A | C27: 5.3892 | D27: 5.3898 | G27: J26 | H27: 2091876 | I27: 863 | J27: 76904 | K27: 7256490165 | L27: 94358.93 | M27: 14.81 | N27: 14.8 | O27: 14.81 | P27: 14.81 | Q27: 14.8 | R27: 94356.54 | S27: -2,39↓ | T27: 14.8 | U27: 14.81 | X27: Q60 | Y27: - | Z27: - | AA27: - | AB27: - | AC27: 9398.55 | AD27: - | AE27: - | AF27: - | AG27: - | AH27: - | AI27: 9373.61 | AJ27: -24,94↓ | AK27: - | AL27: - | AP27: J26 | AQ27: 207950 | AR27: - | AS27: - | AT27: - | AU27: 97742.94 | AV27: - | AW27: - | AX27: - | AY27: - | AZ27: - | BA27: 97470.68 | BB27: -272,26↓ | BC27: - | BD27: - | BG27: J26 | BH27: 20 | BI27: 13996 | BJ27: 690951273 | BK27: 5.14 | BL27: 5.14 | BM27: 5.14 | BN27: 5.14 | BO27: 5.14 | BP27: 5.14 | BQ27: -0,03↓ | BR27: - | BS27: 5.14
A28: 45953 | B28: A | C28: 5.3834 | D28: 5.384 | G28: J27 | H28: 927554 | I28: 1586 | J28: 49521 | K28: 4139064687 | L28: 83620.43 | M28: 13.6 | N28: 13.59 | O28: 13.63 | P28: 13.62 | Q28: 13.59 | R28: 83590.76 | S28: -29,67↓ | T28: 13.59 | U28: 13.59 | X28: X25 | Y28: 4700 | Z28: - | AA28: - | AB28: - | AC28: 99300.18 | AD28: - | AE28: - | AF28: - | AG28: - | AH28: - | AI28: 99283.79 | AJ28: -16,39↓ | AK28: 12.22 | AL28: 13.45 | AP28: J27 | AQ28: 97542 | AR28: 1 | AS28: 28 | AT28: 7012627.7 | AU28: 93444.78 | AV28: 5.05 | AW28: 5.05 | AX28: 5.05 | AY28: 5.05 | AZ28: 5.05 | BA28: 93165.1 | BB28: -279,68↓ | BC28: - | BD28: - | BG28: J27 | BH28: 4 | BI28: 814 | BJ28: 39276293 | BK28: 4.76 | BL28: 4.76 | BM28: 4.78 | BN28: 4.77 | BO28: 4.78 | BP28: 4.78 | BQ28: 0,02↑ | BR28: - | BS28: -
A29: 45954 | B29: A | C29: 5.3791 | D29: 5.3797 | G29: J28 | H29: 238529 | I29: 111 | J29: 1426 | K29: 106002374 | L29: 74434.01 | M29: 13.05 | N29: 13.05 | O29: 13.09 | P29: 13.08 | Q29: 13.06 | R29: 74351.35 | S29: -82,66↓ | T29: 13.06 | U29: - | X29: Z25 | Y29: 659 | Z29: - | AA29: - | AB29: - | AC29: 98447.29 | AD29: - | AE29: - | AF29: - | AG29: - | AH29: - | AI29: 98416.93 | AJ29: -30,36↓ | AK29: 11.94 | AL29: 13.17 | AP29: J28 | AQ29: 44000 | AR29: - | AS29: - | AT29: - | AU29: 89455.37 | AV29: - | AW29: - | AX29: - | AY29: - | AZ29: - | BA29: 89159.78 | BB29: -295,59↓ | BC29: - | BD29: - | BG29: J28 | BH29: 3 | BI29: 626 | BJ29: 29525286 | BK29: 4.73 | BL29: 4.73 | BM29: 4.73 | BN29: 4.73 | BO29: 4.73 | BP29: 4.73 | BQ29: -0,01↓ | BR29: - | BS29: -
A30: 45957 | B30: A | C30: 5.3738 | D30: 5.3744 | G30: J29 | H30: 85200 | I30: 30 | J30: 550 | K30: 36228142 | L30: 65989.35 | M30: 13.13 | N30: 13.1 | O30: 13.13 | P30: 13.11 | Q30: 13.12 | R30: 65872.49 | S30: -116,86↓ | T30: - | U30: - | X30: F26=97.832,59 F27=89.944,35 G26=97.111,09 H26=96.627,98 J26=95.883,92 K27=87.951,85 K29=76.591,49 K33=57.769,41 K35=50.590,04 K45=26.330,55 K55=13.428,25 Q26=92.650,88 Q28=80.501,59 Q30=70.060,85 Q32=60.748,04 Q40=35.508,69 Q50=18.335,59 Q60=9.379,87 X25=99.350,11 Z25=98.482,67 | AP30: J29 | AQ30: 27110 | AR30: - | AS30: - | AT30: - | AU30: 85650.66 | AV30: - | AW30: - | AX30: - | AY30: - | AZ30: - | BA30: 85305.72 | BB30: -344,94↓ | BC30: - | BD30: - | BG30: J29 | BH30: 3 | BI30: 539 | BJ30: 24839734 | BK30: 4.8 | BL30: 4.78 | BM30: 4.8 | BN30: 4.78 | BO30: 4.78 | BP30: 4.78 | BQ30: -0,02↓ | BR30: - | BS30: -
A31: 45958 | B31: A | C31: 5.3684 | D31: 5.369 | G31: J30 | H31: 36550 | I31: 14 | J31: 195 | K31: 11310478 | L31: 58144.53 | M31: 13.26 | N31: 13.25 | O31: 13.26 | P31: 13.25 | Q31: 13.25 | R31: 57992.91 | S31: -151,62↓ | T31: - | U31: - | X31: * Preços de Ajustes Corrigidos Referentes a 28/10/2025 | AP31: J30 | AQ31: 20200 | AR31: - | AS31: - | AT31: - | AU31: 81729.07 | AV31: - | AW31: - | AX31: - | AY31: - | AZ31: - | BA31: 81436.82 | BB31: -292,25↓ | BC31: - | BD31: - | BG31: J30 | BH31: - | BI31: - | BJ31: - | BK31: - | BL31: - | BM31: - | BN31: - | BO31: - | BP31: 4.95 | BQ31: -0,04↓ | BR31: - | BS31: -
A32: 45959 | B32: A | C32: 5.341 | D32: 5.3416 | G32: K26 | H32: 661754 | I32: 20 | J32: 3796 | K32: 354362875 | L32: 93352.49 | M32: 14.76 | N32: 14.75 | O32: 14.76 | P32: 14.75 | Q32: 14.75 | R32: 93352.01 | S32: -0,48↓ | T32: 14.74 | U32: 14.75 | X32: Taxa DI Over para 27/10/2025: 0,0551% | AP32: K26 | AQ32: 63109 | AR32: - | AS32: - | AT32: - | AU32: 97322.66 | AV32: - | AW32: - | AX32: - | AY32: - | AZ32: - | BA32: 97053.27 | BB32: -269,39↓ | BC32: - | BD32: - | BG32: K26 | BH32: 31 | BI32: 8127 | BJ32: 400317619 | BK32: 5.11 | BL32: 5.08 | BM32: 5.12 | BN32: 5.09 | BO32: 5.08 | BP32: 5.08 | BQ32: -0,04↓ | BR32: - | BS32: -
G33: M26 | H33: 250083 | I33: 54 | J33: 283 | K33: 26145433 | L33: 92392.7 | M33: 14.65 | N33: 14.63 | O33: 14.65 | P33: 14.65 | Q33: 14.63 | R33: 92389.98 | S33: -2,72↓ | T33: 14.63 | U33: 14.64 | X33: Valor Índice Ipca pro Rata Tempore: 7.362,9 | AP33: M26 | AQ33: 71500 | AR33: - | AS33: - | AT33: - | AU33: 96976.75 | AV33: - | AW33: - | AX33: - | AY33: - | AZ33: - | BA33: 96704.32 | BB33: -272,43↓ | BC33: - | BD33: - | BG33: M26 | BH33: 9 | BI33: 1774 | BJ33: 87231059 | BK33: 5.03 | BL33: 5.03 | BM33: 5.03 | BN33: 5.03 | BO33: 5.03 | BP33: 5.03 | BQ33: -0,03↓ | BR33: - | BS33: -
G34: N26 | H34: 2701385 | I34: 3567 | J34: 201373 | K34: 18405622958 | L34: 91406.59 | M34: 14.53 | N34: 14.52 | O34: 14.55 | P34: 14.53 | Q34: 14.52 | R34: 91401.71 | S34: -4,88↓ | T34: 14.52 | U34: 14.52 | X34: A taxa e os preços são apenas prévias, não devendo ser considerados definitivos. | AP34: N26 | AQ34: 132856 | AR34: 1 | AS34: 38 | AT34: 9845374.4 | AU34: 96614.67 | AV34: 5.44 | AW34: 5.44 | AX34: 5.44 | AY34: 5.44 | AZ34: 5.44 | BA34: 96337.83 | BB34: -276,84↓ | BC34: - | BD34: - | BG34: N26 | BH34: 7 | BI34: 3150 | BJ34: 376165702 | BK34: 4.98 | BL34: 4.98 | BM34: 4.98 | BN34: 4.98 | BO34: 4.98 | BP34: 4.98 | BQ34: -0,02↓ | BR34: 4.98 | BS34: -
G35: N27 | H35: 1513467 | I35: 5844 | J35: 74268 | K35: 6031026173 | L35: 81259.36 | M35: 13.39 | N35: 13.39 | O35: 13.43 | P35: 13.41 | Q35: 13.39 | R35: 81213.53 | S35: -45,83↓ | T35: 13.39 | U35: 13.4 | AP35: N27 | AQ35: 58420 | AR35: - | AS35: - | AT35: - | AU35: 92500.41 | AV35: - | AW35: - | AX35: - | AY35: - | AZ35: - | BA35: 92206.55 | BB35: -293,86↓ | BC35: - | BD35: - | BG35: N27 | BH35: 1 | BI35: 39 | BJ35: 1872866 | BK35: 4.7 | BL35: 4.7 | BM35: 4.7 | BN35: 4.7 | BO35: 4.7 | BP35: 4.71 | BQ35: 0,01↑ | BR35: - | BS35: -
G36: N28 | H36: 506516 | I36: 3347 | J36: 19569 | K36: 1412687459 | L36: 72286.43 | M36: 13.04 | N36: 13.02 | O36: 13.08 | P36: 13.06 | Q36: 13.06 | R36: 72201.92 | S36: -84,51↓ | T36: 13.05 | U36: 13.07 | AP36: N28 | AQ36: 51850 | AR36: - | AS36: - | AT36: - | AU36: 88592.22 | AV36: - | AW36: - | AX36: - | AY36: - | AZ36: - | BA36: 88317.86 | BB36: -274,36↓ | BC36: - | BD36: - | BG36: N28 | BH36: - | BI36: - | BJ36: - | BK36: - | BL36: - | BM36: - | BN36: - | BO36: - | BP36: 4.69 | BQ36: -0,05↓ | BR36: 4.69 | BS36: -
G37: N29 | H37: 792249 | I37: 1529 | J37: 98973 | K37: 6310407860 | L37: 63887.04 | M37: 13.15 | N37: 13.11 | O37: 13.19 | P37: 13.17 | Q37: 13.16 | R37: 63761.94 | S37: -125,10↓ | T37: 13.16 | U37: 13.18 | AP37: N29 | AQ37: 29350 | AR37: - | AS37: - | AT37: - | AU37: 84719.11 | AV37: - | AW37: - | AX37: - | AY37: - | AZ37: - | BA37: 84369.72 | BB37: -349,39↓ | BC37: - | BD37: - | BG37: N29 | BH37: 2 | BI37: 240 | BJ37: 10991990 | BK37: 4.85 | BL37: 4.8 | BM37: 4.85 | BN37: 4.81 | BO37: 4.8 | BP37: 4.8 | BQ37: -0,05↓ | BR37: 4.81 | BS37: -
G38: N30 | H38: 68008 | I38: 86 | J38: 425 | K38: 23863520 | L38: 56313.64 | M38: 13.3 | N38: 13.29 | O38: 13.31 | P38: 13.3 | Q38: 13.31 | R38: 56147.41 | S38: -166,23↓ | T38: 13.29 | U38: - | AP38: N30 | AQ38: 18170 | AR38: - | AS38: - | AT38: - | AU38: 80746.17 | AV38: - | AW38: - | AX38: - | AY38: - | AZ38: - | BA38: 80452.92 | BB38: -293,25↓ | BC38: - | BD38: - | BG38: N30 | BH38: 1 | BI38: 18 | BJ38: 802807 | BK38: 5 | BL38: 5 | BM38: 5 | BN38: 5 | BO38: 5 | BP38: 5 | BQ38: -0,05↓ | BR38: - | BS38: -
G39: Q26 | H39: 79304 | I39: 3 | J39: 150 | K39: 13552083 | L39: 90352.83 | M39: 14.42 | N39: 14.41 | O39: 14.42 | P39: 14.41 | Q39: 14.41 | R39: 90347.11 | S39: -5,72↓ | T39: 14.4 | U39: 14.41 | AP39: Q26 | AQ39: 42474 | AR39: - | AS39: - | AT39: - | AU39: 96203.78 | AV39: - | AW39: - | AX39: - | AY39: - | AZ39: - | BA39: 95928.16 | BB39: -275,62↓ | BC39: - | BD39: - | BG39: Q26 | BH39: - | BI39: - | BJ39: - | BK39: - | BL39: - | BM39: - | BN39: - | BO39: - | BP39: 4.96 | BQ39: -0,01↓ | BR39: - | BS39: -
G40: Q27 | H40: 38742 | I40: 4 | J40: 84 | K40: 6752454 | L40: 80448.65 | M40: 13.35 | N40: 13.35 | O40: 13.36 | P40: 13.35 | Q40: 13.35 | R40: 80397.21 | S40: -51,44↓ | T40: 13.32 | U40: 13.34 | AP40: Q27 | AQ40: 17725 | AR40: - | AS40: - | AT40: - | AU40: 92127.73 | AV40: - | AW40: - | AX40: - | AY40: - | AZ40: - | BA40: 91833.23 | BB40: -294,50↓ | BC40: - | BD40: - | BG40: Q27 | BH40: 6 | BI40: 480 | BJ40: 22988654 | BK40: 4.72 | BL40: 4.72 | BM40: 4.72 | BN40: 4.72 | BO40: 4.72 | BP40: 4.72 | BQ40: 0,01↑ | BR40: - | BS40: -
G41: U26 | H41: 161407 | I41: 9 | J41: 3259 | K41: 291398995 | L41: 89427.43 | M41: 14.3 | N41: 14.29 | O41: 14.3 | P41: 14.3 | Q41: 14.29 | R41: 89418.96 | S41: -8,47↓ | T41: 14.28 | U41: 14.29 | AP41: U26 | AQ41: 44890 | AR41: - | AS41: - | AT41: - | AU41: 95865.14 | AV41: - | AW41: - | AX41: - | AY41: - | AZ41: - | BA41: 95591.05 | BB41: -274,09↓ | BC41: - | BD41: - | BG41: U26 | BH41: 8 | BI41: 2960 | BJ41: 144694789 | BK41: 4.93 | BL41: 4.93 | BM41: 4.93 | BN41: 4.93 | BO41: 4.93 | BP41: 4.92 | BQ41: -0,01↓ | BR41: - | BS41: 4.93
G42: V26 | H42: 887253 | I42: 1439 | J42: 42656 | K42: 3775572829 | L42: 88527.74 | M42: 14.17 | N42: 14.15 | O42: 14.19 | P42: 14.17 | Q42: 14.16 | R42: 88514.74 | S42: -13,00↓ | T42: 14.16 | U42: 14.16 | AP42: V26 | AQ42: 100301 | AR42: - | AS42: - | AT42: - | AU42: 95523.13 | AV42: - | AW42: - | AX42: - | AY42: - | AZ42: - | BA42: 95232.51 | BB42: -290,62↓ | BC42: - | BD42: - | BG42: V26 | BH42: 10 | BI42: 3424 | BJ42: 167078593 | BK42: 4.88 | BL42: 4.88 | BM42: 4.88 | BN42: 4.88 | BO42: 4.88 | BP42: 4.88 | BQ42: 0 | BR42: - | BS42: -
...

Sheet Curvas
F2: DI1 | I2: DDI | L2: Dólar futuro | O2: FRC | Q2: Cupom Limpo
A3: Código | B3: Vencimento padrão | C3: Vencimento contrato | D3: DC | E3: DU | F3: Ajuste | G3: Fator DI | H3: Curva implícita | I3: Ajuste | J3: Fator DDI | K3: Curva implícita | L3: PTAX_D1 | M3: Variação cambial | N3: Curva implícita | O3: FRA | P3: Curva implícita | Q3: Fator CL | R3: CL_DCL | S3: CL_DOC | T3: Variação Cambial | U3: Curva implícita
A4: =E4&"D" -> 1D | C4: =data_ref_post1 -> 45959 | D4: =C4-data_ref -> 1 | E4: =NETWORKDAYS(data_ref,C4,feriados)-1 -> 1 | F4: =contrato/(1+H4%)^(E4/252) -> 99947.497 | G4: =contrato/F4 -> 1.0005253 | H4: =di -> 14.15 | I4: =contrato/(1+K4*E4/360) -> 105041.82 | J4: =((1+di%)^(E4/252))*(ptax/ptax_ant) -> 0.99952002 | K4: =(J4-1)*360/D4*100 -> -17.279346 | L4: =ptax_ant -> 5.3744 | M4: =G4/J4 -> 1.0010058 | N4: =M4*L4 -> 5.3798054 | Q4: =1+S4/100*D4/360 -> 1.0034379 | R4: =(((1+di%)^(E4/252))*(ptax/DCL)-1)*360/D4*100 -> 87.469934 | S4: =(((1+di%)^(E4/252))*(ptax_ant/DCL)-1)*360/D4*100 -> 123.76577 | U4: =DCL*(((1+di%)^(1/252))/(1+S4%*D4/360)) -> 5.3432453
A5: X25 | B5: ="01/"&VLOOKUP(LEFT(A5,1),$C$49:$D$60,2,0)&"/20"&RIGHT(A5,2) -> 01/11/2025 | C5: =WORKDAY(B5-1,1,feriados) -> 45964 | D5: =C5-data_ref -> 6 | E5: =NETWORKDAYS(data_ref,C5,feriados)-1 -> 4 | F5: =VLOOKUP(A5,'Base de dados'!$G$10:$U$54,12,0) -> 99779.74 | G5: =contrato/F5 -> 1.0022075 | H5: =((contrato/F5)^(252/E5)-1)*100 -> 14.902855 | I5: =VLOOKUP(A5,'Base de dados'!$AP$10:$BD$54,12,0) -> 99536.14 | J5: =contrato/I5 -> 1.0046602 | K5: =((J5-1)*360/D5)*100 -> 27.961301 | L5: =ptax_ant -> 5.3744 | M5: =G5/J5 -> 0.99755862 | N5: =M5*L5 -> 5.3612791 | O5: - | P5: - | Q5: =((1+H5%)^(E5/252))/(N5/DCL) -> 1.001744 | R5: =(Q5-1)*360/D5*100 -> 10.464242 | S5: =((1+K5/100*D5/360)*(DCL/ptax_ant)-1)*360/D5*100 -> 10.464242 | T5: =G5/Q5 -> 1.0004626 | U5: =DCL*T5 -> 5.3612791
A6: Z25 | B6: ="01/"&VLOOKUP(LEFT(A6,1),$C$49:$D$60,2,0)&"/20"&RIGHT(A6,2) -> 01/12/2025 | C6: =WORKDAY(B6-1,1,feriados) -> 45992 | D6: =C6-data_ref -> 34 | E6: =NETWORKDAYS(data_ref,C6,feriados)-1 -> 23 | F6: =VLOOKUP(A6,'Base de dados'!$G$10:$U$54,12,0) -> 98740.1 | G6: =contrato/F6 -> 1.0127598 | H6: =((contrato/F6)^(252/E6)-1)*100 -> 14.903008 | I6: =VLOOKUP(A6,'Base de dados'!$AP$10:$BD$54,12,0) -> 99142.87 | J6: =contrato/I6 -> 1.0086454 | K6: =((J6-1)*360/D6)*100 -> 9.1539554 | L6: =ptax_ant -> 5.3744 | M6: =G6/J6 -> 1.0040791 | N6: =M6*L6 -> 5.3963227 | O6: =(1+K6%*D6/360)/(1+$K$5%*$D$5/360) -> 1.0039667 | P6: =(O6-1)*360/(D6-$D$5)*100 -> 5.1000426 | Q6: =$Q$5*O6 -> 1.0057177 | R6: =(Q6-1)*360/D6*100 -> 6.053991 | S6: =((1+K6/100*D6/360)*(DCL/ptax_ant)-1)*360/D6*100 -> 6.053991 | T6: =G6/Q6 -> 1.0070021 | U6: =DCL*T6 -> 5.3963227
A7: F26 | B7: ="01/"&VLOOKUP(LEFT(A7,1),$C$49:$D$60,2,0)&"/20"&RIGHT(A7,2) -> 01/1/2026 | C7: =WORKDAY(B7-1,1,feriados) -> 46024 | D7: =C7-data_ref -> 66 | E7: =NETWORKDAYS(data_ref,C7,feriados)-1 -> 45 | F7: =VLOOKUP(A7,'Base de dados'!$G$10:$U$54,12,0) -> 97551.05 | G7: =contrato/F7 -> 1.0251043 | H7: =((contrato/F7)^(252/E7)-1)*100 -> 14.894989 | I7: =VLOOKUP(A7,'Base de dados'!$AP$10:$BD$54,12,0) -> 98648.29 | J7: =contrato/I7 -> 1.0137023 | K7: =((J7-1)*360/D7)*100 -> 7.4739903 | L7: =ptax_ant -> 5.3744 | M7: =G7/J7 -> 1.0112479 | N7: =M7*L7 -> 5.4348505 | O7: =(1+K7%*D7/360)/(1+$K$5%*$D$5/360) -> 1.0090002 | P7: =(O7-1)*360/(D7-$D$5)*100 -> 5.4000936 | Q7: =$Q$5*O7 -> 1.0107599 | R7: =(Q7-1)*360/D7*100 -> 5.8690325 | S7: =((1+K7/100*D7/360)*(DCL/ptax_ant)-1)*360/D7*100 -> 5.8690325 | T7: =G7/Q7 -> 1.0141917 | U7: =DCL*T7 -> 5.4348505
A8: G26 | B8: ="01/"&VLOOKUP(LEFT(A8,1),$C$49:$D$60,2,0)&"/20"&RIGHT(A8,2) -> 01/2/2026 | C8: =WORKDAY(B8-1,1,feriados) -> 46055 | D8: =C8-data_ref -> 97 | E8: =NETWORKDAYS(data_ref,C8,feriados)-1 -> 66 | F8: =VLOOKUP(A8,'Base de dados'!$G$10:$U$54,12,0) -> 96431.02 | G8: =contrato/F8 -> 1.0370107 | H8: =((contrato/F8)^(252/E8)-1)*100 -> 14.884987 | I8: =VLOOKUP(A8,'Base de dados'!$AP$10:$BD$54,12,0) -> 98222.84 | J8: =contrato/I8 -> 1.0180931 | K8: =((J8-1)*360/D8)*100 -> 6.7149813 | L8: =ptax_ant -> 5.3744 | M8: =G8/J8 -> 1.0185814 | N8: =M8*L8 -> 5.4742637 | O8: =(1+K8%*D8/360)/(1+$K$5%*$D$5/360) -> 1.0133706 | P8: =(O8-1)*360/(D8-$D$5)*100 -> 5.289475 | Q8: =$Q$5*O8 -> 1.015138 | R8: =(Q8-1)*360/D8*100 -> 5.6182181 | S8: =((1+K8/100*D8/360)*(DCL/ptax_ant)-1)*360/D8*100 -> 5.6182181 | T8: =G8/Q8 -> 1.0215466 | U8: =DCL*T8 -> 5.4742637
A9: H26 | B9: ="01/"&VLOOKUP(LEFT(A9,1),$C$49:$D$60,2,0)&"/20"&RIGHT(A9,2) -> 01/3/2026 | C9: =WORKDAY(B9-1,1,feriados) -> 46083 | D9: =C9-data_ref -> 125 | E9: =NETWORKDAYS(data_ref,C9,feriados)-1 -> 84 | F9: =VLOOKUP(A9,'Base de dados'!$G$10:$U$54,12,0) -> 95487.72 | G9: =contrato/F9 -> 1.0472551 | H9: =((contrato/F9)^(252/E9)-1)*100 -> 14.85699 | I9: =VLOOKUP(A9,'Base de dados'!$AP$10:$BD$54,12,0) -> 97854.01 | J9: =contrato/I9 -> 1.0219305 | K9: =((J9-1)*360/D9)*100 -> 6.3159918 | L9: =ptax_ant -> 5.3744 | M9: =G9/J9 -> 1.0247811 | N9: =M9*L9 -> 5.5075835 | O9: =(1+K9%*D9/360)/(1+$K$5%*$D$5/360) -> 1.0171902 | P9: =(O9-1)*360/(D9-$D$5)*100 -> 5.2003966 | Q9: =$Q$5*O9 -> 1.0189642 | R9: =(Q9-1)*360/D9*100 -> 5.4616956 | S9: =((1+K9/100*D9/360)*(DCL/ptax_ant)-1)*360/D9*100 -> 5.4616956 | T9: =G9/Q9 -> 1.0277643 | U9: =DCL*T9 -> 5.5075835
A10: J26 | B10: ="01/"&VLOOKUP(LEFT(A10,1),$C$49:$D$60,2,0)&"/20"&RIGHT(A10,2) -> 01/4/2026 | C10: =WORKDAY(B10-1,1,feriados) -> 46113 | D10: =C10-data_ref -> 155 | E10: =NETWORKDAYS(data_ref,C10,feriados)-1 -> 106 | F10: =VLOOKUP(A10,'Base de dados'!$G$10:$U$54,12,0) -> 94356.54 | G10: =contrato/F10 -> 1.05981 | H10: =((contrato/F10)^(252/E10)-1)*100 -> 14.809013 | I10: =VLOOKUP(A10,'Base de dados'!$AP$10:$BD$54,12,0) -> 97470.68 | J10: =contrato/I10 -> 1.0259495 | K10: =((J10-1)*360/D10)*100 -> 6.0269916 | L10: =ptax_ant -> 5.3744 | M10: =G10/J10 -> 1.033004 | N10: =M10*L10 -> 5.5517765 | O10: =(1+K10%*D10/360)/(1+$K$5%*$D$5/360) -> 1.0211906 | P10: =(O10-1)*360/(D10-$D$5)*100 -> 5.1198711 | Q10: =$Q$5*O10 -> 1.0229716 | R10: =(Q10-1)*360/D10*100 -> 5.3353336 | S10: =((1+K10/100*D10/360)*(DCL/ptax_ant)-1)*360/D10*100 -> 5.3353336 | T10: =G10/Q10 -> 1.0360111 | U10: =DCL*T10 -> 5.5517765
A11: K26 | B11: ="01/"&VLOOKUP(LEFT(A11,1),$C$49:$D$60,2,0)&"/20"&RIGHT(A11,2) -> 01/5/2026 | C11: =WORKDAY(B11-1,1,feriados) -> 46146 | D11: =C11-data_ref -> 188 | E11: =NETWORKDAYS(data_ref,C11,feriados)-1 -> 126 | F11: =VLOOKUP(A11,'Base de dados'!$G$10:$U$54,12,0) -> 93352.01 | G11: =contrato/F11 -> 1.0712142 | H11: =((contrato/F11)^(252/E11)-1)*100 -> 14.749989 | I11: =VLOOKUP(A11,'Base de dados'!$AP$10:$BD$54,12,0) -> 97053.27 | J11: =contrato/I11 -> 1.030362 | K11: =((J11-1)*360/D11)*100 -> 5.8139973 | L11: =ptax_ant -> 5.3744 | M11: =G11/J11 -> 1.0396484 | N11: =M11*L11 -> 5.5874865 | O11: =(1+K11%*D11/360)/(1+$K$5%*$D$5/360) -> 1.0255825 | P11: =(O11-1)*360/(D11-$D$5)*100 -> 5.0602843 | Q11: =$Q$5*O11 -> 1.0273712 | R11: =(Q11-1)*360/D11*100 -> 5.2412948 | S11: =((1+K11/100*D11/360)*(DCL/ptax_ant)-1)*360/D11*100 -> 5.2412948 | T11: =G11/Q11 -> 1.0426749 | U11: =DCL*T11 -> 5.5874865
A12: M26 | B12: ="01/"&VLOOKUP(LEFT(A12,1),$C$49:$D$60,2,0)&"/20"&RIGHT(A12,2) -> 01/6/2026 | C12: =WORKDAY(B12-1,1,feriados) -> 46174 | D12: =C12-data_ref -> 216 | E12: =NETWORKDAYS(data_ref,C12,feriados)-1 -> 146 | F12: =VLOOKUP(A12,'Base de dados'!$G$10:$U$54,12,0) -> 92389.98 | G12: =contrato/F12 -> 1.0823685 | H12: =((contrato/F12)^(252/E12)-1)*100 -> 14.639006 | I12: =VLOOKUP(A12,'Base de dados'!$AP$10:$BD$54,12,0) -> 96704.32 | J12: =contrato/I12 -> 1.03408 | K12: =((J12-1)*360/D12)*100 -> 5.6799944 | L12: =ptax_ant -> 5.3744 | M12: =G12/J12 -> 1.0466971 | N12: =M12*L12 -> 5.6253687 | O12: =(1+K12%*D12/360)/(1+$K$5%*$D$5/360) -> 1.0292833 | P12: =(O12-1)*360/(D12-$D$5)*100 -> 5.0199914 | Q12: =$Q$5*O12 -> 1.0310784 | R12: =(Q12-1)*360/D12*100 -> 5.1797325 | S12: =((1+K12/100*D12/360)*(DCL/ptax_ant)-1)*360/D12*100 -> 5.1797325 | T12: =G12/Q12 -> 1.0497441 | U12: =DCL*T12 -> 5.6253687
A13: N26 | B13: ="01/"&VLOOKUP(LEFT(A13,1),$C$49:$D$60,2,0)&"/20"&RIGHT(A13,2) -> 01/7/2026 | C13: =WORKDAY(B13-1,1,feriados) -> 46204 | D13: =C13-data_ref -> 246 | E13: =NETWORKDAYS(data_ref,C13,feriados)-1 -> 167 | F13: =VLOOKUP(A13,'Base de dados'!$G$10:$U$54,12,0) -> 91401.71 | G13: =contrato/F13 -> 1.0940714 | H13: =((contrato/F13)^(252/E13)-1)*100 -> 14.529991 | I13: =VLOOKUP(A13,'Base de dados'!$AP$10:$BD$54,12,0) -> 96337.83 | J13: =contrato/I13 -> 1.0380138 | K13: =((J13-1)*360/D13)*100 -> 5.5629997 | L13: =ptax_ant -> 5.3744 | M13: =G13/J13 -> 1.0540047 | N13: =M13*L13 -> 5.6646427 | O13: =(1+K13%*D13/360)/(1+$K$5%*$D$5/360) -> 1.0331989 | P13: =(O13-1)*360/(D13-$D$5)*100 -> 4.979835 | Q13: =$Q$5*O13 -> 1.0350008 | R13: =(Q13-1)*360/D13*100 -> 5.1220742 | S13: =((1+K13/100*D13/360)*(DCL/ptax_ant)-1)*360/D13*100 -> 5.1220742 | T13: =G13/Q13 -> 1.057073 | U13: =DCL*T13 -> 5.6646427
A14: Q26 | B14: ="01/"&VLOOKUP(LEFT(A14,1),$C$49:$D$60,2,0)&"/20"&RIGHT(A14,2) -> 01/8/2026 | C14: =WORKDAY(B14-1,1,feriados) -> 46237 | D14: =C14-data_ref -> 279 | E14: =NETWORKDAYS(data_ref,C14,feriados)-1 -> 190 | F14: =VLOOKUP(A14,'Base de dados'!$G$10:$U$54,12,0) -> 90347.11 | G14: =contrato/F14 -> 1.1068423 | H14: =((contrato/F14)^(252/E14)-1)*100 -> 14.412008 | I14: =VLOOKUP(A14,'Base de dados'!$AP$10:$BD$54,12,0) -> 95928.16 | J14: =contrato/I14 -> 1.0424468 | K14: =((J14-1)*360/D14)*100 -> 5.4770018 | L14: =ptax_ant -> 5.3744 | M14: =G14/J14 -> 1.0617734 | N14: =M14*L14 -> 5.7063951 | O14: =(1+K14%*D14/360)/(1+$K$5%*$D$5/360) -> 1.0376113 | P14: =(O14-1)*360/(D14-$D$5)*100 -> 4.959728 | Q14: =$Q$5*O14 -> 1.0394209 | R14: =(Q14-1)*360/D14*100 -> 5.0865686 | S14: =((1+K14/100*D14/360)*(DCL/ptax_ant)-1)*360/D14*100 -> 5.0865686 | T14: =G14/Q14 -> 1.0648643 | U14: =DCL*T14 -> 5.7063951
A15: U26 | B15: ="01/"&VLOOKUP(LEFT(A15,1),$C$49:$D$60,2,0)&"/20"&RIGHT(A15,2) -> 01/9/2026 | C15: =WORKDAY(B15-1,1,feriados) -> 46266 | D15: =C15-data_ref -> 308 | E15: =NETWORKDAYS(data_ref,C15,feriados)-1 -> 211 | F15: =VLOOKUP(A15,'Base de dados'!$G$10:$U$54,12,0) -> 89418.96 | G15: =contrato/F15 -> 1.1183311 | H15: =((contrato/F15)^(252/E15)-1)*100 -> 14.29 | I15: =VLOOKUP(A15,'Base de dados'!$AP$10:$BD$54,12,0) -> 95591.05 | J15: =contrato/I15 -> 1.046123 | K15: =((J15-1)*360/D15)*100 -> 5.3910049 | L15: =ptax_ant -> 5.3744 | M15: =G15/J15 -> 1.0690244 | N15: =M15*L15 -> 5.7453647 | O15: =(1+K15%*D15/360)/(1+$K$5%*$D$5/360) -> 1.0412705 | P15: =(O15-1)*360/(D15-$D$5)*100 -> 4.9196617 | Q15: =$Q$5*O15 -> 1.0430865 | R15: =(Q15-1)*360/D15*100 -> 5.036086 | S15: =((1+K15/100*D15/360)*(DCL/ptax_ant)-1)*360/D15*100 -> 5.036086 | T15: =G15/Q15 -> 1.0721364 | U15: =DCL*T15 -> 5.7453647
A16: V26 | B16: ="01/"&VLOOKUP(LEFT(A16,1),$C$49:$D$60,2,0)&"/20"&RIGHT(A16,2) -> 01/10/2026 | C16: =WORKDAY(B16-1,1,feriados) -> 46296 | D16: =C16-data_ref -> 338 | E16: =NETWORKDAYS(data_ref,C16,feriados)-1 -> 232 | F16: =VLOOKUP(A16,'Base de dados'!$G$10:$U$54,12,0) -> 88514.74 | G16: =contrato/F16 -> 1.1297553 | H16: =((contrato/F16)^(252/E16)-1)*100 -> 14.170006 | I16: =VLOOKUP(A16,'Base de dados'!$AP$10:$BD$54,12,0) -> 95232.51 | J16: =contrato/I16 -> 1.0500616 | K16: =((J16-1)*360/D16)*100 -> 5.3320027 | L16: =ptax_ant -> 5.3744 | M16: =G16/J16 -> 1.0758944 | N16: =M16*L16 -> 5.7822867 | O16: =(1+K16%*D16/360)/(1+$K$5%*$D$5/360) -> 1.0451908 | P16: =(O16-1)*360/(D16-$D$5)*100 -> 4.9002035 | Q16: =$Q$5*O16 -> 1.0470136 | R16: =(Q16-1)*360/D16*100 -> 5.0073678 | S16: =((1+K16/100*D16/360)*(DCL/ptax_ant)-1)*360/D16*100 -> 5.0073678 | T16: =G16/Q16 -> 1.0790264 | U16: =DCL*T16 -> 5.7822867
A17: X26 | B17: ="01/"&VLOOKUP(LEFT(A17,1),$C$49:$D$60,2,0)&"/20"&RIGHT(A17,2) -> 01/11/2026 | C17: =WORKDAY(B17-1,1,feriados) -> 46329 | D17: =C17-data_ref -> 371 | E17: =NETWORKDAYS(data_ref,C17,feriados)-1 -> 253 | F17: =VLOOKUP(A17,'Base de dados'!$G$10:$U$54,12,0) -> 87634.34 | G17: =contrato/F17 -> 1.1411052 | H17: =((contrato/F17)^(252/E17)-1)*100 -> 14.051 | I17: =VLOOKUP(A17,'Base de dados'!$AP$10:$BD$54,12,0) -> 94852.45 | J17: =contrato/I17 -> 1.054269 | K17: =((J17-1)*360/D17)*100 -> 5.2659971 | L17: =ptax_ant -> 5.3744 | M17: =G17/J17 -> 1.0823662 | N17: =M17*L17 -> 5.8170691 | O17: =(1+K17%*D17/360)/(1+$K$5%*$D$5/360) -> 1.0493787 | P17: =(O17-1)*360/(D17-$D$5)*100 -> 4.8702272 | Q17: =$Q$5*O17 -> 1.0512089 | R17: =(Q17-1)*360/D17*100 -> 4.969053 | S17: =((1+K17/100*D17/360)*(DCL/ptax_ant)-1)*360/D17*100 -> 4.969053 | T17: =G17/Q17 -> 1.0855171 | U17: =DCL*T17 -> 5.8170691
... A45: F40 | B45: ="01/"&VLOOKUP(LEFT(A45,1),$C$49:$D$60,2,0)&"/20"&RIGHT(A45,2) -> 01/1/2040 | C45: =WORKDAY(B45-1,1,feriados) -> 51137 | D45: =C45-data_ref -> 5179 | E45: =NETWORKDAYS(data_ref,C45,feriados)-1 -> 3550 | F45: =VLOOKUP(A45,'Base de dados'!$G$10:$U$54,12,0) -> 17069.24 | G45: =contrato/F45 -> 5.8584916 | H45: =((contrato/F45)^(252/E45)-1)*100 -> 13.371 | I45: =VLOOKUP(A45,'Base de dados'!$AP$10:$BD$54,12,0) -> 47512.5 | J45: =contrato/I45 -> 2.1047093 | K45: =((J45-1)*360/D45)*100 -> 7.6789987 | L45: =ptax_ant -> 5.3744 | M45: =G45/J45 -> 2.7835158 | N45: =M45*L45 -> 14.959728 | O45: =(1+K45%*D45/360)/(1+$K$5%*$D$5/360) -> 2.0949464 | P45: =(O45-1)*360/(D45-$D$5)*100 -> 7.6199632 | Q45: =$Q$5*O45 -> 2.0986001 | R45: =(Q45-1)*360/D45*100 -> 7.6365325 | S45: =((1+K45/100*D45/360)*(DCL/ptax_ant)-1)*360/D45*100 -> 7.6365325 | T45: =G45/Q45 -> 2.7916189 | U45: =DCL*T45 -> 14.959728
C48: Vencimentos | D48: Mês Ref
C49: F | D49: 1
C50: G | D50: 2
C51: H | D51: 3
C52: J | D52: 4
C53: K | D53: 5
C54: M | D54: 6
C55: N | D55: 7
C56: Q | D56: 8
C57: U | D57: 9
C58: V | D58: 10
C59: X | D59: 11
C60: Z | D60: 12

Sheet PnL
A1: DI1 | B1: Alocação | C1: Padrão | D1: Ajustado | E1: DU | F1: Settle | G1: Last | H1: Var bps | I1: PU Aj | J1: Contrato (R$) | K1: DV01 | L1: DV01/PL (bps) | M1: Posição/PL | N1: Carry | O1: Carry to div01 | P1: Carry d0 | Q1: Taxa d0 | R1: MtM
A2: F27 | B2: 0 | C2: ="01/"&VLOOKUP(LEFT(A2,1),$G$31:$H$42,2,0)&"/20"&RIGHT(A2,2) -> 01/1/2027 | D2: =WORKDAY(C2-1,1,feriados) -> 46391 | E2: =NETWORKDAYS($C$31,D2,feriados)-1 -> 107 | F2: =IF(RTD("rtdtrading.rtdserver",,$A$1&A2,"AJA")=0,RTD("rtdtrading.rtdserver",,$A$1&A2,"FEC"),RTD("rtdtrading.rtdserver",,$A$1&A2,"AJA")) -> 13.873 | G2: =IF(RTD("rtdtrading.rtdserver",,$A$1&A2,"AJU")=0,RTD("rtdtrading.rtdserver",,$A$1&A2,"ULT"),RTD("rtdtrading.rtdserver",,$A$1&A2,"AJU")) -> 13.842 | H2: =(G2-F2)*100 -> -3.1 | I2: =contrato/(1+F2%)^(E2/252) -> 94633.209 | J2: =I2 -> 94633.209 | K2: =I2-contrato/(1+F2%+0.01%)^(E2/252) -> 3.5284086 | L2: =K2*B2/pl*10000 -> 0 | M2: =J2*B2/pl -> 0 | N2: =(((1+F2%)^(1/252))/(1+di_dia%)-1)*I2 -> -0.91237264 | O2: =N2/K2 -> -0.25857908 | P2: =B2*N2 -> 0 | Q2: =-B2*K2*H2 -> 0 | R2: =IFERROR(Q2+P2,0) -> 0 | T2: PL Atualizado | U2: 6529110
A3: J27 | B3: 0 | C3: ="01/"&VLOOKUP(LEFT(A3,1),$G$31:$H$42,2,0)&"/20"&RIGHT(A3,2) -> 01/4/2027 | D3: =WORKDAY(C3-1,1,feriados) -> 46478 | E3: =NETWORKDAYS($C$31,D3,feriados)-1 -> 167 | F3: =IF(RTD("rtdtrading.rtdserver",,$A$1&A3,"AJA")=0,RTD("rtdtrading.rtdserver",,$A$1&A3,"FEC"),RTD("rtdtrading.rtdserver",,$A$1&A3,"AJA")) -> 13.908 | G3: =IF(RTD("rtdtrading.rtdserver",,$A$1&A3,"AJU")=0,RTD("rtdtrading.rtdserver",,$A$1&A3,"ULT"),RTD("rtdtrading.rtdserver",,$A$1&A3,"AJU")) -> 13.872 | H3: =(G3-F3)*100 -> -3.6 | I3: =contrato/(1+F3%)^(E3/252) -> 91732.157 | J3: =I3 -> 91732.157 | K3: =I3-contrato/(1+F3%+0.01%)^(E3/252) -> 5.3364398 | L3: =K3*B3/pl*10000 -> 0 | M3: =J3*B3/pl -> 0 | N3: =(((1+F3%)^(1/252))/(1+di_dia%)-1)*I3 -> -0.77253728 | O3: =N3/K3 -> -0.14476642 | P3: =B3*N3 -> 0 | Q3: =-B3*K3*H3 -> 0 | R3: =IFERROR(Q3+P3,0) -> 0
A4: N27 | B4: 0 | C4: ="01/"&VLOOKUP(LEFT(A4,1),$G$31:$H$42,2,0)&"/20"&RIGHT(A4,2) -> 01/7/2027 | D4: =WORKDAY(C4-1,1,feriados) -> 46569 | E4: =NETWORKDAYS($C$31,D4,feriados)-1 -> 230 | F4: =IF(RTD("rtdtrading.rtdserver",,$A$1&A4,"AJA")=0,RTD("rtdtrading.rtdserver",,$A$1&A4,"FEC"),RTD("rtdtrading.rtdserver",,$A$1&A4,"AJA")) -> 13.934 | G4: =IF(RTD("rtdtrading.rtdserver",,$A$1&A4,"AJU")=0,RTD("rtdtrading.rtdserver",,$A$1&A4,"ULT"),RTD("rtdtrading.rtdserver",,$A$1&A4,"AJU")) -> 13.894 | H4: =(G4-F4)*100 -> -4 | I4: =contrato/(1+F4%)^(E4/252) -> 88775.389 | J4: =I4 -> 88775.389 | K4: =I4-contrato/(1+F4%+0.01%)^(E4/252) -> 7.1109902 | L4: =K4*B4/pl*10000 -> 0 | M4: =J4*B4/pl -> 0 | N4: =(((1+F4%)^(1/252))/(1+di_dia%)-1)*I4 -> -0.66723599 | O4: =N4/K4 -> -0.093831657 | P4: =B4*N4 -> 0 | Q4: =-B4*K4*H4 -> 0 | R4: =IFERROR(Q4+P4,0) -> 0 | T4: PnL | U4: Carry | V4: Taxa | W4: MtM
A5: F28 | B5: =16+5 -> 21 | C5: ="01/"&VLOOKUP(LEFT(A5,1),$G$31:$H$42,2,0)&"/20"&RIGHT(A5,2) -> 01/1/2028 | D5: =WORKDAY(C5-1,1,feriados) -> 46755 | E5: =NETWORKDAYS($C$31,D5,feriados)-1 -> 358 | F5: =IF(RTD("rtdtrading.rtdserver",,$A$1&A5,"AJA")=0,RTD("rtdtrading.rtdserver",,$A$1&A5,"FEC"),RTD("rtdtrading.rtdserver",,$A$1&A5,"AJA")) -> 13.976 | G5: =IF(RTD("rtdtrading.rtdserver",,$A$1&A5,"AJU")=0,RTD("rtdtrading.rtdserver",,$A$1&A5,"ULT"),RTD("rtdtrading.rtdserver",,$A$1&A5,"AJU")) -> 13.942 | H5: =(G5-F5)*100 -> -3.4 | I5: =contrato/(1+F5%)^(E5/252) -> 83040.295 | J5: =I5 -> 83040.295 | K5: =I5-contrato/(1+F5%+0.01%)^(E5/252) -> 10.349321 | L5: =K5*B5/pl*10000 -> 0.33287191 | M5: =J5*B5/pl -> 0.26708789 | N5: =(((1+F5%)^(1/252))/(1+di_dia%)-1)*I5 -> -0.50267996 | O5: =N5/K5 -> -0.0485713 | P5: =B5*N5 -> -10.556279 | Q5: =-B5*K5*H5 -> 738.94149 | R5: =IFERROR(Q5+P5,0) -> 728.38522 | T5: Pré | U5: =SUM(P2:P15)/pl*10000 -> -0.0043152515 | V5: =SUM(Q2:Q15)/pl*10000 -> 3.6888125 | W5: =SUM(U5:V5) -> 3.6844973
A6: N28 | B6: 0 | C6: ="01/"&VLOOKUP(LEFT(A6,1),$G$31:$H$42,2,0)&"/20"&RIGHT(A6,2) -> 01/7/2028 | D6: =WORKDAY(C6-1,1,feriados) -> 46937 | E6: =NETWORKDAYS($C$31,D6,feriados)-1 -> 482 | F6: =IF(RTD("rtdtrading.rtdserver",,$A$1&A6,"AJA")=0,RTD("rtdtrading.rtdserver",,$A$1&A6,"FEC"),RTD("rtdtrading.rtdserver",,$A$1&A6,"AJA")) -> 14.096 | G6: =IF(RTD("rtdtrading.rtdserver",,$A$1&A6,"AJU")=0,RTD("rtdtrading.rtdserver",,$A$1&A6,"ULT"),RTD("rtdtrading.rtdserver",,$A$1&A6,"AJU")) -> 14.067 | H6: =(G6-F6)*100 -> -2.9 | I6: =contrato/(1+F6%)^(E6/252) -> 77706.788 | J6: =I6 -> 77706.788 | K6: =I6-contrato/(1+F6%+0.01%)^(E6/252) -> 13.025056 | L6: =K6*B6/pl*10000 -> 0 | M6: =J6*B6/pl -> 0 | N6: =(((1+F6%)^(1/252))/(1+di_dia%)-1)*I6 -> -0.14590783 | O6: =N6/K6 -> -0.011202088 | P6: =B6*N6 -> 0 | Q6: =-B6*K6*H6 -> 0 | R6: =IFERROR(Q6+P6,0) -> 0 | T6: Juro Real | U6: =SUM(P17:P26)/pl*10000 -> 0 | V6: =SUM(Q17:Q26)/pl*10000 -> 0 | W6: =SUM(U6:V6) -> 0
A7: F29 | B7: =55-13-5+5 -> 42 | C7: ="01/"&VLOOKUP(LEFT(A7,1),$G$31:$H$42,2,0)&"/20"&RIGHT(A7,2) -> 01/1/2029 | D7: =WORKDAY(C7-1,1,feriados) -> 47120 | E7: =NETWORKDAYS($C$31,D7,feriados)-1 -> 606 | F7: =IF(RTD("rtdtrading.rtdserver",,$A$1&A7,"AJA")=0,RTD("rtdtrading.rtdserver",,$A$1&A7,"FEC"),RTD("rtdtrading.rtdserver",,$A$1&A7,"AJA")) -> 14.223 | G7: =IF(RTD("rtdtrading.rtdserver",,$A$1&A7,"AJU")=0,RTD("rtdtrading.rtdserver",,$A$1&A7,"ULT"),RTD("rtdtrading.rtdserver",,$A$1&A7,"AJU")) -> 14.197 | H7: =(G7-F7)*100 -> -2.6 | I7: =contrato/(1+F7%)^(E7/252) -> 72630.065 | J7: =I7 -> 72630.065 | K7: =I7-contrato/(1+F7%+0.01%)^(E7/252) -> 15.288688 | L7: =K7*B7/pl*10000 -> 0.98348001 | M7: =J7*B7/pl -> 0.46720958 | N7: =(((1+F7%)^(1/252))/(1+di_dia%)-1)*I7 -> 0.18425724 | O7: =N7/K7 -> 0.012051867 | P7: =B7*N7 -> 7.738804 | Q7: =-B7*K7*H7 -> 1669.5248 | R7: =IFERROR(Q7+P7,0) -> 1677.2636 | T7: Moeda | U7: =SUM(P28)/pl*10000 -> 0 | V7: =SUM(Q28)/pl*10000 -> 0 | W7: =SUM(U7:V7) -> 0
A8: N29 | B8: 0 | C8: ="01/"&VLOOKUP(LEFT(A8,1),$G$31:$H$42,2,0)&"/20"&RIGHT(A8,2) -> 01/7/2029 | D8: =WORKDAY(C8-1,1,feriados) -> 47301 | E8: =NETWORKDAYS($C$31,D8,feriados)-1 -> 730 | F8: =IF(RTD("rtdtrading.rtdserver",,$A$1&A8,"AJA")=0,RTD("rtdtrading.rtdserver",,$A$1&A8,"FEC"),RTD("rtdtrading.rtdserver",,$A$1&A8,"AJA")) -> 14.333 | G8: =IF(RTD("rtdtrading.rtdserver",,$A$1&A8,"AJU")=0,RTD("rtdtrading.rtdserver",,$A$1&A8,"ULT"),RTD("rtdtrading.rtdserver",,$A$1&A8,"AJU")) -> 14.311 | H8: =(G8-F8)*100 -> -2.2 | I8: =contrato/(1+F8%)^(E8/252) -> 67840.187 | J8: =I8 -> 67840.187 | K8: =I8-contrato/(1+F8%+0.01%)^(E8/252) -> 17.185562 | L8: =K8*B8/pl*10000 -> 0 | M8: =J8*B8/pl -> 0 | N8: =(((1+F8%)^(1/252))/(1+di_dia%)-1)*I8 -> 0.43123615 | O8: =N8/K8 -> 0.025092932 | P8: =B8*N8 -> 0 | Q8: =-B8*K8*H8 -> 0 | R8: =IFERROR(Q8+P8,0) -> 0 | T8: Bps | U8: =SUM(U5:U7) -> -0.0043152515 | V8: =SUM(V5:V7) -> 3.6888125 | W8: =SUM(W5:W7) -> 3.6844973
A9: F30 | B9: 0 | C9: ="01/"&VLOOKUP(LEFT(A9,1),$G$31:$H$42,2,0)&"/20"&RIGHT(A9,2) -> 01/1/2030 | D9: =WORKDAY(C9-1,1,feriados) -> 47485 | E9: =NETWORKDAYS($C$31,D9,feriados)-1 -> 855 | F9: =IF(RTD("rtdtrading.rtdserver",,$A$1&A9,"AJA")=0,RTD("rtdtrading.rtdserver",,$A$1&A9,"FEC"),RTD("rtdtrading.rtdserver",,$A$1&A9,"AJA")) -> 14.385 | G9: =IF(RTD("rtdtrading.rtdserver",,$A$1&A9,"AJU")=0,RTD("rtdtrading.rtdserver",,$A$1&A9,"ULT"),RTD("rtdtrading.rtdserver",,$A$1&A9,"AJU")) -> 14.366 | H9: =(G9-F9)*100 -> -1.9 | I9: =contrato/(1+F9%)^(E9/252) -> 63381.434 | J9: =I9 -> 63381.434 | K9: =I9-contrato/(1+F9%+0.01%)^(E9/252) -> 18.796421 | L9: =K9*B9/pl*10000 -> 0 | M9: =J9*B9/pl -> 0 | N9: =(((1+F9%)^(1/252))/(1+di_dia%)-1)*I9 -> 0.51725963 | O9: =N9/K9 -> 0.027519048 | P9: =B9*N9 -> 0 | Q9: =-B9*K9*H9 -> 0 | R9: =IFERROR(Q9+P9,0) -> 0
A10: F31 | B10: 0 | C10: ="01/"&VLOOKUP(LEFT(A10,1),$G$31:$H$42,2,0)&"/20"&RIGHT(A10,2) -> 01/1/2031 | D10: =WORKDAY(C10-1,1,feriados) -> 47850 | E10: =NETWORKDAYS($C$31,D10,feriados)-1 -> 1107 | F10: =IF(RTD("rtdtrading.rtdserver",,$A$1&A10,"AJA")=0,RTD("rtdtrading.rtdserver",,$A$1&A10,"FEC"),RTD("rtdtrading.rtdserver",,$A$1&A10,"AJA")) -> 14.467 | G10: =IF(RTD("rtdtrading.rtdserver",,$A$1&A10,"AJU")=0,RTD("rtdtrading.rtdserver",,$A$1&A10,"ULT"),RTD("rtdtrading.rtdserver",,$A$1&A10,"AJU")) -> 14.45 | H10: =(G10-F10)*100 -> -1.7 | I10: =contrato/(1+F10%)^(E10/252) -> 55236.458 | J10: =I10 -> 55236.458 | K10: =I10-contrato/(1+F10%+0.01%)^(E10/252) -> 21.192896 | L10: =K10*B10/pl*10000 -> 0 | M10: =J10*B10/pl -> 0 | N10: =(((1+F10%)^(1/252))/(1+di_dia%)-1)*I10 -> 0.60786717 | O10: =N10/K10 -> 0.028682591 | P10: =B10*N10 -> 0 | Q10: =-B10*K10*H10 -> 0 | R10: =IFERROR(Q10+P10,0) -> 0
A11: F32 | B11: 0 | C11: ="01/"&VLOOKUP(LEFT(A11,1),$G$31:$H$42,2,0)&"/20"&RIGHT(A11,2) -> 01/1/2032 | D11: =WORKDAY(C11-1,1,feriados) -> 48215 | E11: =NETWORKDAYS($C$31,D11,feriados)-1 -> 1359 | F11: =IF(RTD("rtdtrading.rtdserver",,$A$1&A11,"AJA")=0,RTD("rtdtrading.rtdserver",,$A$1&A11,"FEC"),RTD("rtdtrading.rtdserver",,$A$1&A11,"AJA")) -> 14.559 | G11: =IF(RTD("rtdtrading.rtdserver",,$A$1&A11,"AJU")=0,RTD("rtdtrading.rtdserver",,$A$1&A11,"ULT"),RTD("rtdtrading.rtdserver",,$A$1&A11,"AJU")) -> 14.543 | H11: =(G11-F11)*100 -> -1.6 | I11: =contrato/(1+F11%)^(E11/252) -> 48046.735 | J11: =I11 -> 48046.735 | K11: =I11-contrato/(1+F11%+0.01%)^(E11/252) -> 22.611658 | L11: =K11*B11/pl*10000 -> 0 | M11: =J11*B11/pl -> 0 | N11: =(((1+F11%)^(1/252))/(1+di_dia%)-1)*I11 -> 0.68192551 | O11: =N11/K11 -> 0.030158138 | P11: =B11*N11 -> 0 | Q11: =-B11*K11*H11 -> 0 | R11: =IFERROR(Q11+P11,0) -> 0 | T11: Posições | U11: Notional | V11: % PL | W11: DV01 | X11: DV01 Bps
A12: F33 | B12: 0 | C12: ="01/"&VLOOKUP(LEFT(A12,1),$G$31:$H$42,2,0)&"/20"&RIGHT(A12,2) -> 01/1/2033 | D12: =WORKDAY(C12-1,1,feriados) -> 48582 | E12: =NETWORKDAYS($C$31,D12,feriados)-1 -> 1611 | F12: =IF(RTD("rtdtrading.rtdserver",,$A$1&A12,"AJA")=0,RTD("rtdtrading.rtdserver",,$A$1&A12,"FEC"),RTD("rtdtrading.rtdserver",,$A$1&A12,"AJA")) -> 14.686 | G12: =IF(RTD("rtdtrading.rtdserver",,$A$1&A12,"AJU")=0,RTD("rtdtrading.rtdserver",,$A$1&A12,"ULT"),RTD("rtdtrading.rtdserver",,$A$1&A12,"AJU")) -> 14.592 | H12: =(G12-F12)*100 -> -9.4 | I12: =contrato/(1+F12%)^(E12/252) -> 41644.579 | J12: =I12 -> 41644.579 | K12: =I12-contrato/(1+F12%+0.01%)^(E12/252) -> 23.206151 | L12: =K12*B12/pl*10000 -> 0 | M12: =J12*B12/pl -> 0 | N12: =(((1+F12%)^(1/252))/(1+di_dia%)-1)*I12 -> 0.77416442 | O12: =N12/K12 -> 0.033360312 | P12: =B12*N12 -> 0 | Q12: =-B12*K12*H12 -> 0 | R12: =IFERROR(Q12+P12,0) -> 0 | T12: Pré | U12: =SUMPRODUCT(B2:B15,J2:J15) -> 4794308.9 | V12: =U12/pl -> 0.73429747 | W12: =SUMPRODUCT(K2:K15,B2:B15) -> 859.46065 | X12: =W12/pl*10000 -> 1.3163519
A13: F34 | B13: 0 | C13: ="01/"&VLOOKUP(LEFT(A13,1),$G$31:$H$42,2,0)&"/20"&RIGHT(A13,2) -> 01/1/2034 | D13: =WORKDAY(C13-1,1,feriados) -> 48946 | E13: =NETWORKDAYS($C$31,D13,feriados)-1 -> 1862 | F13: =IF(RTD("rtdtrading.rtdserver",,$A$1&A13,"AJA")=0,RTD("rtdtrading.rtdserver",,$A$1&A13,"FEC"),RTD("rtdtrading.rtdserver",,$A$1&A13,"AJA")) -> 14.618 | G13: =IF(RTD("rtdtrading.rtdserver",,$A$1&A13,"AJU")=0,RTD("rtdtrading.rtdserver",,$A$1&A13,"ULT"),RTD("rtdtrading.rtdserver",,$A$1&A13,"AJU")) -> 14.611 | H13: =(G13-F13)*100 -> -0.7 | I13: =contrato/(1+F13%)^(E13/252) -> 36491.142 | J13: =I13 -> 36491.142 | K13: =I13-contrato/(1+F13%+0.01%)^(E13/252) -> 23.515534 | L13: =K13*B13/pl*10000 -> 0 | M13: =J13*B13/pl -> 0 | N13: =(((1+F13%)^(1/252))/(1+di_dia%)-1)*I13 -> 0.59247716 | O13: =N13/K13 -> 0.02519514 | P13: =B13*N13 -> 0 | Q13: =-B13*K13*H13 -> 0 | R13: =IFERROR(Q13+P13,0) -> 0 | T13: Juro Real | U13: =SUMPRODUCT(B17:B26,J17:J26) -> 0 | V13: =U13/pl -> 0 | W13: =SUMPRODUCT(K17:K26,B17:B26) -> 0 | X13: =W13/pl*10000 -> 0
A14: F35 | B14: 0 | C14: ="01/"&VLOOKUP(LEFT(A14,1),$G$31:$H$42,2,0)&"/20"&RIGHT(A14,2) -> 01/1/2035 | D14: =WORKDAY(C14-1,1,feriados) -> 49311 | E14: =NETWORKDAYS($C$31,D14,feriados)-1 -> 2110 | F14: =IF(RTD("rtdtrading.rtdserver",,$A$1&A14,"AJA")=0,RTD("rtdtrading.rtdserver",,$A$1&A14,"FEC"),RTD("rtdtrading.rtdserver",,$A$1&A14,"AJA")) -> 14.64 | G14: =IF(RTD("rtdtrading.rtdserver",,$A$1&A14,"AJU")=0,RTD("rtdtrading.rtdserver",,$A$1&A14,"ULT"),RTD("rtdtrading.rtdserver",,$A$1&A14,"AJU")) -> 14.63 | H14: =(G14-F14)*100 -> -1 | I14: =contrato/(1+F14%)^(E14/252) -> 31854.973 | J14: =I14 -> 31854.973 | K14: =I14-contrato/(1+F14%+0.01%)^(E14/252) -> 23.256559 | L14: =K14*B14/pl*10000 -> 0 | M14: =J14*B14/pl -> 0 | N14: =(((1+F14%)^(1/252))/(1+di_dia%)-1)*I14 -> 0.54146463 | O14: =N14/K14 -> 0.023282233 | P14: =B14*N14 -> 0 | Q14: =-B14*K14*H14 -> 0 | R14: =IFERROR(Q14+P14,0) -> 0 | T14: Net Juros BZ | U14: =SUM(U12:U13) -> 4794308.9 | V14: =SUM(V12:V13) -> 0.73429747 | W14: =SUM(W12:W13) -> 859.46065 | X14: =SUM(X12:X13) -> 1.3163519
A15: F37 | B15: 0 | C15: ="01/"&VLOOKUP(LEFT(A15,1),$G$31:$H$42,2,0)&"/20"&RIGHT(A15,2) -> 01/1/2037 | D15: =WORKDAY(C15-1,1,feriados) -> 50042 | E15: =NETWORKDAYS($C$31,D15,feriados)-1 -> 2612 | F15: =IF(RTD("rtdtrading.rtdserver",,$A$1&A15,"AJA")=0,RTD("rtdtrading.rtdserver",,$A$1&A15,"FEC"),RTD("rtdtrading.rtdserver",,$A$1&A15,"AJA")) -> 14.662 | G15: =IF(RTD("rtdtrading.rtdserver",,$A$1&A15,"AJU")=0,RTD("rtdtrading.rtdserver",,$A$1&A15,"ULT"),RTD("rtdtrading.rtdserver",,$A$1&A15,"AJU")) -> 14.671 | H15: =(G15-F15)*100 -> 0.9 | I15: =contrato/(1+F15%)^(E15/252) -> 24216.537 | J15: =I15 -> 24216.537 | K15: =I15-contrato/(1+F15%+0.01%)^(E15/252) -> 21.880132 | L15: =K15*B15/pl*10000 -> 0 | M15: =J15*B15/pl -> 0 | N15: =(((1+F15%)^(1/252))/(1+di_dia%)-1)*I15 -> 0.4300681 | O15: =N15/K15 -> 0.019655645 | P15: =B15*N15 -> 0 | Q15: =-B15*K15*H15 -> 0 | R15: =IFERROR(Q15+P15,0) -> 0
A16: DAP | T16: Posições | U16: Notional | V16: % PL
A17: Q26 | B17: 0 | C17: 15/8/2026 | D17: =WORKDAY(C17-1,1,feriados) -> 46251 | E17: =NETWORKDAYS($C$31,D17,feriados)-1 -> 13 | F17: =IF(RTD("rtdtrading.rtdserver",,$A$16&A17,"AJA")=0,RTD("rtdtrading.rtdserver",,$A$16&A17,"FEC"),RTD("rtdtrading.rtdserver",,$A$16&A17,"AJA")) -> 15.524 | G17: =IF(RTD("rtdtrading.rtdserver",,$A$16&A17,"AJU")=0,RTD("rtdtrading.rtdserver",,$A$16&A17,"ULT"),RTD("rtdtrading.rtdserver",,$A$16&A17,"AJU")) -> 13.9 | H17: =(G17-F17)*100 -> -162.4 | I17: =contrato/(1+F17%)^(E17/252) -> 99258.318 | J17: =I17*$C$43 -> 183749.46 | K17: =(I17-contrato/(1+F17%+0.01%)^(E17/252))*rs_dap -> 0.81764819 | L17: =K17*B17/pl*10000 -> 0 | M17: =J17*B17/pl -> 0 | N17: =(((1+G17%)^(1/252)*(1+$C$41%)^(1/$C$39))/(1+di_dia%)-1)*J17 -> 2.3948757 | O17: =N17/K17 -> 2.9289806 | P17: =B17*N17 -> 0 | Q17: =-B17*K17*H17 -> 0 | R17: =IFERROR(Q17+P17,0) -> 0 | T17: USDBRL | U17: =SUMPRODUCT(J28,B28) -> 0 | V17: =U17/pl -> 0
A18: K27 | B18: 0 | C18: 15/5/2027 | D18: =WORKDAY(C18-1,1,feriados) -> 46524 | E18: =NETWORKDAYS($C$31,D18,feriados)-1 -> 198 | F18: =IF(RTD("rtdtrading.rtdserver",,$A$16&A18,"AJA")=0,RTD("rtdtrading.rtdserver",,$A$16&A18,"FEC"),RTD("rtdtrading.rtdserver",,$A$16&A18,"AJA")) -> 8.81 | G18: =IF(RTD("rtdtrading.rtdserver",,$A$16&A18,"AJU")=0,RTD("rtdtrading.rtdserver",,$A$16&A18,"ULT"),RTD("rtdtrading.rtdserver",,$A$16&A18,"AJU")) -> 8.78 | H18: =(G18-F18)*100 -> -3 | I18: =contrato/(1+F18%)^(E18/252) -> 93581.239 | J18: =I18*$C$43 -> 173239.91 | K18: =(I18-contrato/(1+F18%+0.01%)^(E18/252))*rs_dap -> 12.465157 | L18: =K18*B18/pl*10000 -> 0 | M18: =J18*B18/pl -> 0 | N18: =(((1+G18%)^(1/252)*(1+$C$41%)^(1/$C$39))/(1+di_dia%)-1)*J18 -> -29.358231 | O18: =N18/K18 -> -2.3552236 | P18: =B18*N18 -> 0 | Q18: =-B18*K18*H18 -> 0 | R18: =IFERROR(Q18+P18,0) -> 0 | T18: Net FX | U18: =SUM(U17:U17) -> 0 | V18: =SUM(V17:V17) -> 0
A19: Q28 | B19: 0 | C19: 15/8/2028 | D19: =WORKDAY(C19-1,1,feriados) -> 46980 | E19: =NETWORKDAYS($C$31,D19,feriados)-1 -> 513 | F19: =IF(RTD("rtdtrading.rtdserver",,$A$16&A19,"AJA")=0,RTD("rtdtrading.rtdserver",,$A$16&A19,"FEC"),RTD("rtdtrading.rtdserver",,$A$16&A19,"AJA")) -> 8.52 | G19: =IF(RTD("rtdtrading.rtdserver",,$A$16&A19,"AJU")=0,RTD("rtdtrading.rtdserver",,$A$16&A19,"ULT"),RTD("rtdtrading.rtdserver",,$A$16&A19,"AJU")) -> 8.575 | H19: =(G19-F19)*100 -> 5.5 | I19: =contrato/(1+F19%)^(E19/252) -> 84666.62 | J19: =I19*$C$43 -> 156736.95 | K19: =(I19-contrato/(1+F19%+0.01%)^(E19/252))*rs_dap -> 29.295928 | L19: =K19*B19/pl*10000 -> 0 | M19: =J19*B19/pl -> 0 | N19: =(((1+G19%)^(1/252)*(1+$C$41%)^(1/$C$39))/(1+di_dia%)-1)*J19 -> -27.734576 | O19: =N19/K19 -> -0.94670412 | P19: =B19*N19 -> 0 | Q19: =-B19*K19*H19 -> 0 | R19: =IFERROR(Q19+P19,0) -> 0
A20: K29 | B20: 0 | C20: 15/5/2029 | D20: =WORKDAY(C20-1,1,feriados) -> 47253 | E20: =NETWORKDAYS($C$31,D20,feriados)-1 -> 697 | F20: =IF(RTD("rtdtrading.rtdserver",,$A$16&A20,"AJA")=0,RTD("rtdtrading.rtdserver",,$A$16&A20,"FEC"),RTD("rtdtrading.rtdserver",,$A$16&A20,"AJA")) -> 8.325 | G20: =IF(RTD("rtdtrading.rtdserver",,$A$16&A20,"AJU")=0,RTD("rtdtrading.rtdserver",,$A$16&A20,"ULT"),RTD("rtdtrading.rtdserver",,$A$16&A20,"AJU")) -> 8.39 | H20: =(G20-F20)*100 -> 6.5 | I20: =contrato/(1+F20%)^(E20/252) -> 80157.623 | J20: =I20*$C$43 -> 148389.78 | K20: =(I20-contrato/(1+F20%+0.01%)^(E20/252))*rs_dap -> 37.750406 | L20: =K20*B20/pl*10000 -> 0 | M20: =J20*B20/pl -> 0 | N20: =(((1+G20%)^(1/252)*(1+$C$41%)^(1/$C$39))/(1+di_dia%)-1)*J20 -> -27.261555 | O20: =N20/K20 -> -0.72215261 | P20: =B20*N20 -> 0 | Q20: =-B20*K20*H20 -> 0 | R20: =IFERROR(Q20+P20,0) -> 0
A21: Q30 | B21: 0 | C21: 15/8/2030 | D21: =WORKDAY(C21-1,1,feriados) -> 47710 | E21: =NETWORKDAYS($C$31,D21,feriados)-1 -> 1011 | F21: =IF(RTD("rtdtrading.rtdserver",,$A$16&A21,"AJA")=0,RTD("rtdtrading.rtdserver",,$A$16&A21,"FEC"),RTD("rtdtrading.rtdserver",,$A$16&A21,"AJA")) -> 8.335 | G21: =IF(RTD("rtdtrading.rtdserver",,$A$16&A21,"AJU")=0,RTD("rtdtrading.rtdserver",,$A$16&A21,"ULT"),RTD("rtdtrading.rtdserver",,$A$16&A21,"AJU")) -> 8.4 | H21: =(G21-F21)*100 -> 6.5 | I21: =contrato/(1+F21%)^(E21/252) -> 72528.874 | J21: =I21*$C$43 -> 134267.25 | K21: =(I21-contrato/(1+F21%+0.01%)^(E21/252))*rs_dap -> 49.538295 | L21: =K21*B21/pl*10000 -> 0 | M21: =J21*B21/pl -> 0 | N21: =(((1+G21%)^(1/252)*(1+$C$41%)^(1/$C$39))/(1+di_dia%)-1)*J21 -> -24.617877 | O21: =N21/K21 -> -0.49694639 | P21: =B21*N21 -> 0 | Q21: =-B21*K21*H21 -> 0 | R21: =IFERROR(Q21+P21,0) -> 0
A22: Q32 | B22: 0 | C22: 15/8/2032 | D22: =WORKDAY(C22-1,1,feriados) -> 48442 | E22: =NETWORKDAYS($C$31,D22,feriados)-1 -> 1515 | F22: =IF(RTD("rtdtrading.rtdserver",,$A$16&A22,"AJA")=0,RTD("rtdtrading.rtdserver",,$A$16&A22,"FEC"),RTD("rtdtrading.rtdserver",,$A$16&A22,"AJA")) -> 8.29 | G22: =IF(RTD("rtdtrading.rtdserver",,$A$16&A22,"AJU")=0,RTD("rtdtrading.rtdserver",,$A$16&A22,"ULT"),RTD("rtdtrading.rtdserver",,$A$16&A22,"AJU")) -> 8.34 | H22: =(G22-F22)*100 -> 5 | I22: =contrato/(1+F22%)^(E22/252) -> 61952.397 | J22: =I22*$C$43 -> 114687.81 | K22: =(I22-contrato/(1+F22%+0.01%)^(E22/252))*rs_dap -> 63.429312 | L22: =K22*B22/pl*10000 -> 0 | M22: =J22*B22/pl -> 0 | N22: =(((1+G22%)^(1/252)*(1+$C$41%)^(1/$C$39))/(1+di_dia%)-1)*J22 -> -21.27992 | O22: =N22/K22 -> -0.33549031 | P22: =B22*N22 -> 0 | Q22: =-B22*K22*H22 -> 0 | R22: =IFERROR(Q22+P22,0) -> 0
A23: K33 | B23: 0 | C23: 15/5/2033 | D23: =WORKDAY(C23-1,1,feriados) -> 48715 | E23: =NETWORKDAYS($C$31,D23,feriados)-1 -> 1702 | F23: =IF(RTD("rtdtrading.rtdserver",,$A$16&A23,"AJA")=0,RTD("rtdtrading.rtdserver",,$A$16&A23,"FEC"),RTD("rtdtrading.rtdserver",,$A$16&A23,"AJA")) -> 8.25 | G23: =IF(RTD("rtdtrading.rtdserver",,$A$16&A23,"AJU")=0,RTD("rtdtrading.rtdserver",,$A$16&A23,"ULT"),RTD("rtdtrading.rtdserver",,$A$16&A23,"AJU")) -> 8.285 | H23: =(G23-F23)*100 -> 3.5 | I23: =contrato/(1+F23%)^(E23/252) -> 58543.007 | J23: =I23*$C$43 -> 108376.27 | K23: =(I23-contrato/(1+F23%+0.01%)^(E23/252))*rs_dap -> 67.359576 | L23: =K23*B23/pl*10000 -> 0 | M23: =J23*B23/pl -> 0 | N23: =(((1+G23%)^(1/252)*(1+$C$41%)^(1/$C$39))/(1+di_dia%)-1)*J23 -> -20.327176 | O23: =N23/K23 -> -0.30177114 | P23: =B23*N23 -> 0 | Q23: =-B23*K23*H23 -> 0 | R23: =IFERROR(Q23+P23,0) -> 0
